Workbook
Name AMR_NB_Br: Report!$B$53:$C$53
Name AMR_WB_Br: Report!$B$54:$D$54
Name Bitrate: Report!$D$15
Name CDMA_Vc_Bw: Report!$B$47:$D$47
Name EVS_NB_Br: Report!$B$55:$D$55
Name EVS_SWB_Br: Report!$B$57:$D$57
Name EVS_WB_Br: Report!$B$56:$D$56
Name GSM_Vc_Bw: Report!$B$45:$C$45
Name HardwareVersions: Report!$A$63:$F$63
Name HeadsetTypes: Report!$A$66:$D$66
Name InterfaceType: Report!$B$13
Name InterfaceTypes: Report!$A$65:$C$65
Name Network: Report!$B$15
Name Networks: Report!$A$45:$A$51
Name SO3_NB_Br: Report!$B$58
Name SO68_NB_Br: Report!$B$58
Name SO73_NB_Br: Report!$B$58
Name SO73_WB_Br: Report!$B$59
Name SWB_Br: Report!$B$61:$C$61
Name VCBW: Report!$C$15
Name VoIP_Vc_Bw: Report!$B$49:$C$49
Name VoLTE_Vc_Bw: Report!$B$48:$F$48
Name VoNR_Vc_Bw: Report!$B$50:$F$50
Name VoWiFi_Vc_Bw: Report!$B$51:$F$51
Name WB_Br: Report!$B$60:$D$60
Name WCDMA_Vc_Bw: Report!$B$46:$C$46

Sheet Report
A1: Voice Tuning Checklist
A3: · Select or input the design information of the device into the Basic Info form. (Input the product name and Track ID for Motorola devices into Module Number cell.)
A4: · Mark the cells of Report Files to Green if completed the test and saved the required result files, mark it to Yellow if something miss, mark it to Red if miss the test.
A6: Basic Info
A7: Item | B7: Value
A8: Serial Number
A9: Model Number
A10: Hardware Version
A11: Build Number
A12: Item | B12: Type | C12: Adapter | D12: Headset
A13: Headset Interface | B13: USB-C Analog + Digital
A14: Item | B14: Network | C14: Vocoder | D14: Bitrate
A15: Test Network | B15: VoLTE | C15: AMR_NB | D15: 12.2kbit/s
A17: Handset
A18: Test Case | B18: Report Files | C18: Naming Rule
A19: 3GPP TS126.131/132 | B19: doc | C19: =$A$17&"_"&$B$15&"_"&$C$15&"_"&SUBSTITUTE($A19," ","_") -> Handset_VoLTE_AMR_NB_3GPP_TS126.131/132
A20: Robustaness | B20: doc | C20: =$A$17&"_"&$B$15&"_"&$C$15&"_"&SUBSTITUTE($A20," ","_") -> Handset_VoLTE_AMR_NB_Robustaness
A21: POLQA MOS | B21: doc | C21: =$A$17&"_"&$B$15&"_"&$C$15&"_"&SUBSTITUTE($A21," ","_") -> Handset_VoLTE_AMR_NB_POLQA_MOS
A23: Handsfree
A24: Test Case | B24: Report Files | C24: Naming Rule
A25: 3GPP TS126.131/132 | B25: doc | C25: =$A$23&"_"&$B$15&"_"&$C$15&"_"&SUBSTITUTE($A25," ","_") -> Handsfree_VoLTE_AMR_NB_3GPP_TS126.131/132
A26: POLQA MOS | B26: doc | C26: =$A$23&"_"&$B$15&"_"&$C$15&"_"&SUBSTITUTE($A26," ","_") -> Handsfree_VoLTE_AMR_NB_POLQA_MOS
A28: Headset
A29: Test Case | B29: Report Files | C29: Naming Rule
A30: 3GPP TS126.131/132 | B30: doc | C30: =$A$28&"_"&$B$15&"_"&$C$15&"_"&SUBSTITUTE($A30," ","_") -> Headset_VoLTE_AMR_NB_3GPP_TS126.131/132
A31: POLQA MOS | B31: doc | C31: =$A$28&"_"&$B$15&"_"&$C$15&"_"&SUBSTITUTE($A31," ","_") -> Headset_VoLTE_AMR_NB_POLQA_MOS
A33: Bluetooth
A34: Test Case | B34: Report Files | C34: Naming Rule
A35: Acoustic TRD | B35: doc | C35: =$A$33&"_"&$B$15&"_"&$C$15&"_"&SUBSTITUTE($A35," ","_") -> Bluetooth_VoLTE_AMR_NB_Acoustic_TRD
A36: POLQA MOS | B36: doc | C36: =$A$33&"_"&$B$15&"_"&$C$15&"_"&SUBSTITUTE($A36," ","_") -> Bluetooth_VoLTE_AMR_NB_POLQA_MOS
A38: Electrical Interface
A39: Test Case | B39: Report Files | C39: Naming Rule
A40: 3GPP TS126.131/132 | B40: doc | C40: =$A$38&"_"&$B$15&"_"&$C$15&"_"&SUBSTITUTE($A40," ","_") -> Electrical Interface_VoLTE_AMR_NB_3GPP_TS126.131/132
A41: P.381 | B41: doc | C41: =$A$38&"_"&$B$15&"_"&$C$15&"_"&SUBSTITUTE($A41," ","_") -> Electrical Interface_VoLTE_AMR_NB_P.381
A43: Control Values
A44: Networks | B44: Vocoder_Bandwidth
A45: GSM | B45: AMR_NB | C45: AMR_WB
A46: WCDMA | B46: AMR_NB | C46: AMR_WB
A47: CDMA | B47: SO3_NB | C47: SO68_NB | D47: SO73_NB | E47: SO73_WB
A48: VoLTE | B48: AMR_NB | C48: AMR_WB | D48: EVS_NB | E48: EVS_WB | F48: EVS_SWB
...

Sheet Handset
A1: Voice Tuning Checklist - Handset
A3: Test Condition | E3: Criteria | I3: =Report!B15 -> VoLTE | J3: =Report!C15 -> AMR_NB | K3: =Report!D15 -> 12.2kbit/s | M3: NB | N3: WB | O3: SWB | P3: NB | Q3: WB | R3: SWB | T3: UMTS AMR_NB | U3: UMTS AMR_WB | V3: VoIMS AMR_NB | W3: VoIMS AMR_WB | X3: VoIMS EVS_NB | Y3: VoIMS EVS_WB | Z3: VoIMS EVS_SWB | AA3: CDMA SO3_NB | AB3: CDMA SO68_NB | AC3: CDMA SO73_NB | AD3: CDMA SO73_WB | AE3: VoIP WB | AF3: VoIP SWB | AG3: UMTS AMR_NB | AH3: UMTS AMR_WB | AI3: VoIMS AMR_NB | AJ3: VoIMS AMR_WB | AK3: VoIMS EVS_NB | AL3: VoIMS EVS_WB | AM3: VoIMS EVS_SWB | AN3: CDMA SO3_NB | AO3: CDMA SO68_NB | AP3: CDMA SO73_NB | AQ3: CDMA SO73_WB | AR3: VoIP WB | AS3: VoIP SWB
A4: Item | B4: Standard | C4: Subitem | D4: Settings | E4: lower | F4: upper | G4: unit | H4: type | I4: =IF(ISBLANK(Report!B8),"",ISBLANK(Report!B8)) | J4: =IF(ISBLANK(Report!C8),"",ISBLANK(Report!C8)) | K4: =IF(ISBLANK(Report!D8),"",ISBLANK(Report!D8))
A5: 3GPP TS126.131/132 | M5: NB | N5: WB | O5: SWB | P5: NB | Q5: WB | R5: SWB | T5: AMR_NB | U5: AMR_WB | V5: AMR_NB | W5: AMR_WB | X5: EVS_NB | Y5: EVS_WB | Z5: EVS_SWB | AA5: SO3_NB | AB5: SO68_NB | AC5: SO73_NB | AD5: SO73_WB | AE5: WB | AF5: SWB | AG5: AMR_NB | AH5: AMR_WB | AI5: AMR_NB | AJ5: AMR_WB | AK5: EVS_NB | AL5: EVS_WB | AM5: EVS_SWB | AN5: SO3_NB | AO5: SO68_NB | AP5: SO73_NB | AQ5: SO73_WB | AR5: WB | AS5: SWB
A6: Overall loss/loudness ratings | B6: =HLOOKUP(SUBSTITUTE(SUBSTITUTE(SUBSTITUTE(SUBSTITUTE(SUBSTITUTE(VCBW,"AMR_",""),"EVS_",""),"SO3_",""),"SO68_",""),"SO73_",""),$M$3:$O$75,ROW(B6)-ROW($M$3)+1,FALSE)&IF(ISBLANK(HLOOKUP(SUBSTITUTE(SUBSTITUTE(SUBSTITUTE(SUBSTITUTE(SUBSTITUTE(VCBW,"AMR_",""),"EVS_",""),"SO3_",""),"SO68_",""),"SO73_",""),$P$3:$R$75,ROW(B6)-ROW($P$3)+1,FALSE)), ""," / "&HLOOKUP(SUBSTITUTE(SUBSTITUTE(SUBSTITUTE(SUBSTITUTE(SUBSTITUTE(VCBW,"AMR_",""),"EVS_",""),"SO3_",""),"SO68_",""),"SO73_",""),$P$3:$R$75,ROW(B6)-ROW($P$3)+1,FALSE)) -> 5.2.2 / 7.2.2.1 | C6: Sending (SLR) | E6: =HLOOKUP(IF(OR("GSM"=Network,"WCDMA"=Network),"UMTS",IF(OR("VoLTE"=Network,"VoNR"=Network,"VoWiFi"=Network),"VoIMS",Network))&" "&VCBW,$T$3:$AF$75,ROW(E6)-ROW($T$3)+1,FALSE) -> 5 | F6: =HLOOKUP(IF(OR("GSM"=Network,"WCDMA"=Network),"UMTS",IF(OR("VoLTE"=Network,"VoNR"=Network,"VoWiFi"=Network),"VoIMS",Network))&" "&VCBW,$AG$3:$AS$75,ROW(E6)-ROW($AG$3)+1,FALSE) -> 11 | G6: dB | H6: 1 | M6: 5.2.2 | N6: 6.2.2 | O6: 7.2.2 | P6: 7.2.2.1 | Q6: 8.2.2.1 | R6: 9.2.2.1 | T6: 5 | U6: 5 | V6: 5 | W6: 5 | X6: 5 | Y6: 5 | Z6: 5 | AA6: 5 | AB6: 5 | AC6: 5 | AD6: 5 | AE6: 5 | AF6: 5 | AG6: 11 | AH6: 11 | AI6: 11 | AJ6: 11 | AK6: 11 | AL6: 11 | AM6: 11 | AN6: 11 | AO6: 11 | AP6: 11 | AQ6: 11 | AR6: 11 | AS6: 11
B7: =HLOOKUP(SUBSTITUTE(SUBSTITUTE(SUBSTITUTE(SUBSTITUTE(SUBSTITUTE(VCBW,"AMR_",""),"EVS_",""),"SO3_",""),"SO68_",""),"SO73_",""),$M$3:$O$75,ROW(B7)-ROW($M$3)+1,FALSE)&IF(ISBLANK(HLOOKUP(SUBSTITUTE(SUBSTITUTE(SUBSTITUTE(SUBSTITUTE(SUBSTITUTE(VCBW,"AMR_",""),"EVS_",""),"SO3_",""),"SO68_",""),"SO73_",""),$P$3:$R$75,ROW(B7)-ROW($P$3)+1,FALSE)), ""," / "&HLOOKUP(SUBSTITUTE(SUBSTITUTE(SUBSTITUTE(SUBSTITUTE(SUBSTITUTE(VCBW,"AMR_",""),"EVS_",""),"SO3_",""),"SO68_",""),"SO73_",""),$P$3:$R$75,ROW(B7)-ROW($P$3)+1,FALSE)) -> 5.2.2 / 7.2.2.2 | C7: Receiving (RLR) | D7: max vol. | E7: =HLOOKUP(IF(OR("GSM"=Network,"WCDMA"=Network),"UMTS",IF(OR("VoLTE"=Network,"VoNR"=Network,"VoWiFi"=Network),"VoIMS",Network))&" "&VCBW,$T$3:$AF$75,ROW(E7)-ROW($T$3)+1,FALSE) -> -13 | F7: =HLOOKUP(IF(OR("GSM"=Network,"WCDMA"=Network),"UMTS",IF(OR("VoLTE"=Network,"VoNR"=Network,"VoWiFi"=Network),"VoIMS",Network))&" "&VCBW,$AG$3:$AS$75,ROW(E7)-ROW($AG$3)+1,FALSE) -> -10 | G7: dB | H7: 1 | M7: 5.2.2 | N7: 6.2.2 | O7: 7.2.2 | P7: 7.2.2.2 | Q7: 8.2.2.2 | R7: 9.2.2.2 | T7: -13 | U7: -13 | V7: -13 | W7: -13 | X7: -13 | Y7: -13 | Z7: -13 | AA7: -13 | AB7: -13 | AC7: -13 | AD7: -13 | AE7: -13 | AF7: -13 | AG7: -10 | AH7: -10 | AI7: -10 | AJ7: -10 | AK7: -10 | AL7: -10 | AM7: -10 | AN7: -10 | AO7: -10 | AP7: -10 | AQ7: -10 | AR7: -10 | AS7: -10
B8: =HLOOKUP(SUBSTITUTE(SUBSTITUTE(SUBSTITUTE(SUBSTITUTE(SUBSTITUTE(VCBW,"AMR_",""),"EVS_",""),"SO3_",""),"SO68_",""),"SO73_",""),$M$3:$O$75,ROW(B8)-ROW($M$3)+1,FALSE)&IF(ISBLANK(HLOOKUP(SUBSTITUTE(SUBSTITUTE(SUBSTITUTE(SUBSTITUTE(SUBSTITUTE(VCBW,"AMR_",""),"EVS_",""),"SO3_",""),"SO68_",""),"SO73_",""),$P$3:$R$75,ROW(B8)-ROW($P$3)+1,FALSE)), ""," / "&HLOOKUP(SUBSTITUTE(SUBSTITUTE(SUBSTITUTE(SUBSTITUTE(SUBSTITUTE(VCBW,"AMR_",""),"EVS_",""),"SO3_",""),"SO68_",""),"SO73_",""),$P$3:$R$75,ROW(B8)-ROW($P$3)+1,FALSE)) -> 5.2.2 / 7.2.2.2 | D8: max-1 vol. | E8: =HLOOKUP(IF(OR("GSM"=Network,"WCDMA"=Network),"UMTS",IF(OR("VoLTE"=Network,"VoNR"=Network,"VoWiFi"=Network),"VoIMS",Network))&" "&VCBW,$T$3:$AF$75,ROW(E8)-ROW($T$3)+1,FALSE) -> -10 | F8: =HLOOKUP(IF(OR("GSM"=Network,"WCDMA"=Network),"UMTS",IF(OR("VoLTE"=Network,"VoNR"=Network,"VoWiFi"=Network),"VoIMS",Network))&" "&VCBW,$AG$3:$AS$75,ROW(E8)-ROW($AG$3)+1,FALSE) -> -4 | G8: dB | H8: 4 | J8: × | K8: × | M8: 5.2.2 | N8: 6.2.2 | O8: 7.2.2 | P8: 7.2.2.2 | Q8: 8.2.2.2 | R8: 9.2.2.2 | T8: -10 | U8: -10 | V8: -10 | W8: -10 | X8: -10 | Y8: -10 | Z8: -10 | AA8: -10 | AB8: -10 | AC8: -10 | AD8: -10 | AE8: -10 | AF8: -10 | AG8: -4 | AH8: -4 | AI8: -4 | AJ8: -4 | AK8: -4 | AL8: -4 | AM8: -4 | AN8: -4 | AO8: -4 | AP8: -4 | AQ8: -4 | AR8: -4 | AS8: -4
B9: =HLOOKUP(SUBSTITUTE(SUBSTITUTE(SUBSTITUTE(SUBSTITUTE(SUBSTITUTE(VCBW,"AMR_",""),"EVS_",""),"SO3_",""),"SO68_",""),"SO73_",""),$M$3:$O$75,ROW(B9)-ROW($M$3)+1,FALSE)&IF(ISBLANK(HLOOKUP(SUBSTITUTE(SUBSTITUTE(SUBSTITUTE(SUBSTITUTE(SUBSTITUTE(VCBW,"AMR_",""),"EVS_",""),"SO3_",""),"SO68_",""),"SO73_",""),$P$3:$R$75,ROW(B9)-ROW($P$3)+1,FALSE)), ""," / "&HLOOKUP(SUBSTITUTE(SUBSTITUTE(SUBSTITUTE(SUBSTITUTE(SUBSTITUTE(VCBW,"AMR_",""),"EVS_",""),"SO3_",""),"SO68_",""),"SO73_",""),$P$3:$R$75,ROW(B9)-ROW($P$3)+1,FALSE)) -> 5.2.2 / 7.2.2.2 | D9: max-2 vol. | E9: =HLOOKUP(IF(OR("GSM"=Network,"WCDMA"=Network),"UMTS",IF(OR("VoLTE"=Network,"VoNR"=Network,"VoWiFi"=Network),"VoIMS",Network))&" "&VCBW,$T$3:$AF$75,ROW(E9)-ROW($T$3)+1,FALSE) -> -7 | F9: =HLOOKUP(IF(OR("GSM"=Network,"WCDMA"=Network),"UMTS",IF(OR("VoLTE"=Network,"VoNR"=Network,"VoWiFi"=Network),"VoIMS",Network))&" "&VCBW,$AG$3:$AS$75,ROW(E9)-ROW($AG$3)+1,FALSE) -> -1 | G9: dB | H9: 4 | J9: × | K9: × | M9: 5.2.2 | N9: 6.2.2 | O9: 7.2.2 | P9: 7.2.2.2 | Q9: 8.2.2.2 | R9: 9.2.2.2 | T9: -7 | U9: -7 | V9: -7 | W9: -7 | X9: -7 | Y9: -7 | Z9: -7 | AA9: -7 | AB9: -7 | AC9: -7 | AD9: -7 | AE9: -7 | AF9: -7 | AG9: -1 | AH9: -1 | AI9: -1 | AJ9: -1 | AK9: -1 | AL9: -1 | AM9: -1 | AN9: -1 | AO9: -1 | AP9: -1 | AQ9: -1 | AR9: -1 | AS9: -1
B10: =HLOOKUP(SUBSTITUTE(SUBSTITUTE(SUBSTITUTE(SUBSTITUTE(SUBSTITUTE(VCBW,"AMR_",""),"EVS_",""),"SO3_",""),"SO68_",""),"SO73_",""),$M$3:$O$75,ROW(B10)-ROW($M$3)+1,FALSE)&IF(ISBLANK(HLOOKUP(SUBSTITUTE(SUBSTITUTE(SUBSTITUTE(SUBSTITUTE(SUBSTITUTE(VCBW,"AMR_",""),"EVS_",""),"SO3_",""),"SO68_",""),"SO73_",""),$P$3:$R$75,ROW(B10)-ROW($P$3)+1,FALSE)), ""," / "&HLOOKUP(SUBSTITUTE(SUBSTITUTE(SUBSTITUTE(SUBSTITUTE(SUBSTITUTE(VCBW,"AMR_",""),"EVS_",""),"SO3_",""),"SO68_",""),"SO73_",""),$P$3:$R$75,ROW(B10)-ROW($P$3)+1,FALSE)) -> 5.2.2 / 7.2.2.2 | D10: max-3 vol. | E10: =HLOOKUP(IF(OR("GSM"=Network,"WCDMA"=Network),"UMTS",IF(OR("VoLTE"=Network,"VoNR"=Network,"VoWiFi"=Network),"VoIMS",Network))&" "&VCBW,$T$3:$AF$75,ROW(E10)-ROW($T$3)+1,FALSE) -> -4 | F10: =HLOOKUP(IF(OR("GSM"=Network,"WCDMA"=Network),"UMTS",IF(OR("VoLTE"=Network,"VoNR"=Network,"VoWiFi"=Network),"VoIMS",Network))&" "&VCBW,$AG$3:$AS$75,ROW(E10)-ROW($AG$3)+1,FALSE) -> 2 | G10: dB | H10: 4 | J10: × | K10: × | M10: 5.2.2 | N10: 6.2.2 | O10: 7.2.2 | P10: 7.2.2.2 | Q10: 8.2.2.2 | R10: 9.2.2.2 | T10: -4 | U10: -4 | V10: -4 | W10: -4 | X10: -4 | Y10: -4 | Z10: -4 | AA10: -4 | AB10: -4 | AC10: -4 | AD10: -4 | AE10: -4 | AF10: -4 | AG10: 2 | AH10: 2 | AI10: 2 | AJ10: 2 | AK10: 2 | AL10: 2 | AM10: 2 | AN10: 2 | AO10: 2 | AP10: 2 | AQ10: 2 | AR10: 2 | AS10: 2
B11: =HLOOKUP(SUBSTITUTE(SUBSTITUTE(SUBSTITUTE(SUBSTITUTE(SUBSTITUTE(VCBW,"AMR_",""),"EVS_",""),"SO3_",""),"SO68_",""),"SO73_",""),$M$3:$O$75,ROW(B11)-ROW($M$3)+1,FALSE)&IF(ISBLANK(HLOOKUP(SUBSTITUTE(SUBSTITUTE(SUBSTITUTE(SUBSTITUTE(SUBSTITUTE(VCBW,"AMR_",""),"EVS_",""),"SO3_",""),"SO68_",""),"SO73_",""),$P$3:$R$75,ROW(B11)-ROW($P$3)+1,FALSE)), ""," / "&HLOOKUP(SUBSTITUTE(SUBSTITUTE(SUBSTITUTE(SUBSTITUTE(SUBSTITUTE(VCBW,"AMR_",""),"EVS_",""),"SO3_",""),"SO68_",""),"SO73_",""),$P$3:$R$75,ROW(B11)-ROW($P$3)+1,FALSE)) -> 5.2.2 / 7.2.2.2 | D11: max-4 (nom) vol. | E11: =HLOOKUP(IF(OR("GSM"=Network,"WCDMA"=Network),"UMTS",IF(OR("VoLTE"=Network,"VoNR"=Network,"VoWiFi"=Network),"VoIMS",Network))&" "&VCBW,$T$3:$AF$75,ROW(E11)-ROW($T$3)+1,FALSE) -> -1 | F11: =HLOOKUP(IF(OR("GSM"=Network,"WCDMA"=Network),"UMTS",IF(OR("VoLTE"=Network,"VoNR"=Network,"VoWiFi"=Network),"VoIMS",Network))&" "&VCBW,$AG$3:$AS$75,ROW(E11)-ROW($AG$3)+1,FALSE) -> 5 | G11: dB | H11: 1 | M11: 5.2.2 | N11: 6.2.2 | O11: 7.2.2 | P11: 7.2.2.2 | Q11: 8.2.2.2 | R11: 9.2.2.2 | T11: -1 | U11: -1 | V11: -1 | W11: -1 | X11: -1 | Y11: -1 | Z11: -1 | AA11: -1 | AB11: -1 | AC11: -1 | AD11: -1 | AE11: -1 | AF11: -1 | AG11: 5 | AH11: 5 | AI11: 5 | AJ11: 5 | AK11: 5 | AL11: 5 | AM11: 5 | AN11: 5 | AO11: 5 | AP11: 5 | AQ11: 5 | AR11: 5 | AS11: 5
B12: =HLOOKUP(SUBSTITUTE(SUBSTITUTE(SUBSTITUTE(SUBSTITUTE(SUBSTITUTE(VCBW,"AMR_",""),"EVS_",""),"SO3_",""),"SO68_",""),"SO73_",""),$M$3:$O$75,ROW(B12)-ROW($M$3)+1,FALSE)&IF(ISBLANK(HLOOKUP(SUBSTITUTE(SUBSTITUTE(SUBSTITUTE(SUBSTITUTE(SUBSTITUTE(VCBW,"AMR_",""),"EVS_",""),"SO3_",""),"SO68_",""),"SO73_",""),$P$3:$R$75,ROW(B12)-ROW($P$3)+1,FALSE)), ""," / "&HLOOKUP(SUBSTITUTE(SUBSTITUTE(SUBSTITUTE(SUBSTITUTE(SUBSTITUTE(VCBW,"AMR_",""),"EVS_",""),"SO3_",""),"SO68_",""),"SO73_",""),$P$3:$R$75,ROW(B12)-ROW($P$3)+1,FALSE)) -> 5.2.2 / 7.2.2.2 | D12: max-5 vol. | E12: =HLOOKUP(IF(OR("GSM"=Network,"WCDMA"=Network),"UMTS",IF(OR("VoLTE"=Network,"VoNR"=Network,"VoWiFi"=Network),"VoIMS",Network))&" "&VCBW,$T$3:$AF$75,ROW(E12)-ROW($T$3)+1,FALSE) -> 2 | F12: =HLOOKUP(IF(OR("GSM"=Network,"WCDMA"=Network),"UMTS",IF(OR("VoLTE"=Network,"VoNR"=Network,"VoWiFi"=Network),"VoIMS",Network))&" "&VCBW,$AG$3:$AS$75,ROW(E12)-ROW($AG$3)+1,FALSE) -> 12 | G12: dB | H12: 4 | J12: × | K12: × | M12: 5.2.2 | N12: 6.2.2 | O12: 7.2.2 | P12: 7.2.2.2 | Q12: 8.2.2.2 | R12: 9.2.2.2 | T12: 2 | U12: 2 | V12: 2 | W12: 2 | X12: 2 | Y12: 2 | Z12: 2 | AA12: 2 | AB12: 2 | AC12: 2 | AD12: 2 | AE12: 2 | AF12: 2 | AG12: 12 | AH12: 12 | AI12: 12 | AJ12: 12 | AK12: 12 | AL12: 12 | AM12: 12 | AN12: 12 | AO12: 12 | AP12: 12 | AQ12: 12 | AR12: 12 | AS12: 12
B13: =HLOOKUP(SUBSTITUTE(SUBSTITUTE(SUBSTITUTE(SUBSTITUTE(SUBSTITUTE(VCBW,"AMR_",""),"EVS_",""),"SO3_",""),"SO68_",""),"SO73_",""),$M$3:$O$75,ROW(B13)-ROW($M$3)+1,FALSE)&IF(ISBLANK(HLOOKUP(SUBSTITUTE(SUBSTITUTE(SUBSTITUTE(SUBSTITUTE(SUBSTITUTE(VCBW,"AMR_",""),"EVS_",""),"SO3_",""),"SO68_",""),"SO73_",""),$P$3:$R$75,ROW(B13)-ROW($P$3)+1,FALSE)), ""," / "&HLOOKUP(SUBSTITUTE(SUBSTITUTE(SUBSTITUTE(SUBSTITUTE(SUBSTITUTE(VCBW,"AMR_",""),"EVS_",""),"SO3_",""),"SO68_",""),"SO73_",""),$P$3:$R$75,ROW(B13)-ROW($P$3)+1,FALSE)) -> 5.2.2 / 7.2.2.2 | D13: max-6 vol. | E13: =HLOOKUP(IF(OR("GSM"=Network,"WCDMA"=Network),"UMTS",IF(OR("VoLTE"=Network,"VoNR"=Network,"VoWiFi"=Network),"VoIMS",Network))&" "&VCBW,$T$3:$AF$75,ROW(E13)-ROW($T$3)+1,FALSE) -> 5 | F13: =HLOOKUP(IF(OR("GSM"=Network,"WCDMA"=Network),"UMTS",IF(OR("VoLTE"=Network,"VoNR"=Network,"VoWiFi"=Network),"VoIMS",Network))&" "&VCBW,$AG$3:$AS$75,ROW(E13)-ROW($AG$3)+1,FALSE) -> 15 | G13: dB | H13: 4 | J13: × | K13: × | M13: 5.2.2 | N13: 6.2.2 | O13: 7.2.2 | P13: 7.2.2.2 | Q13: 8.2.2.2 | R13: 9.2.2.2 | T13: 5 | U13: 5 | V13: 5 | W13: 5 | X13: 5 | Y13: 5 | Z13: 5 | AA13: 5 | AB13: 5 | AC13: 5 | AD13: 5 | AE13: 5 | AF13: 5 | AG13: 15 | AH13: 15 | AI13: 15 | AJ13: 15 | AK13: 15 | AL13: 15 | AM13: 15 | AN13: 15 | AO13: 15 | AP13: 15 | AQ13: 15 | AR13: 15 | AS13: 15
B14: =HLOOKUP(SUBSTITUTE(SUBSTITUTE(SUBSTITUTE(SUBSTITUTE(SUBSTITUTE(VCBW,"AMR_",""),"EVS_",""),"SO3_",""),"SO68_",""),"SO73_",""),$M$3:$O$75,ROW(B14)-ROW($M$3)+1,FALSE)&IF(ISBLANK(HLOOKUP(SUBSTITUTE(SUBSTITUTE(SUBSTITUTE(SUBSTITUTE(SUBSTITUTE(VCBW,"AMR_",""),"EVS_",""),"SO3_",""),"SO68_",""),"SO73_",""),$P$3:$R$75,ROW(B14)-ROW($P$3)+1,FALSE)), ""," / "&HLOOKUP(SUBSTITUTE(SUBSTITUTE(SUBSTITUTE(SUBSTITUTE(SUBSTITUTE(VCBW,"AMR_",""),"EVS_",""),"SO3_",""),"SO68_",""),"SO73_",""),$P$3:$R$75,ROW(B14)-ROW($P$3)+1,FALSE)) -> 5.2.2 / 7.2.2.2 | D14: max-7 (min) vol. | E14: =HLOOKUP(IF(OR("GSM"=Network,"WCDMA"=Network),"UMTS",IF(OR("VoLTE"=Network,"VoNR"=Network,"VoWiFi"=Network),"VoIMS",Network))&" "&VCBW,$T$3:$AF$75,ROW(E14)-ROW($T$3)+1,FALSE) -> 8 | F14: =HLOOKUP(IF(OR("GSM"=Network,"WCDMA"=Network),"UMTS",IF(OR("VoLTE"=Network,"VoNR"=Network,"VoWiFi"=Network),"VoIMS",Network))&" "&VCBW,$AG$3:$AS$75,ROW(E14)-ROW($AG$3)+1,FALSE) -> 18 | G14: dB | H14: 1 | M14: 5.2.2 | N14: 6.2.2 | O14: 7.2.2 | P14: 7.2.2.2 | Q14: 8.2.2.2 | R14: 9.2.2.2 | T14: 8 | U14: 8 | V14: 8 | W14: 8 | X14: 8 | Y14: 8 | Z14: 8 | AA14: 8 | AB14: 8 | AC14: 8 | AD14: 8 | AE14: 8 | AF14: 8 | AG14: 18 | AH14: 18 | AI14: 18 | AJ14: 18 | AK14: 18 | AL14: 18 | AM14: 18 | AN14: 18 | AO14: 18 | AP14: 18 | AQ14: 18 | AR14: 18 | AS14: 18
B15: =HLOOKUP(SUBSTITUTE(SUBSTITUTE(SUBSTITUTE(SUBSTITUTE(SUBSTITUTE(VCBW,"AMR_",""),"EVS_",""),"SO3_",""),"SO68_",""),"SO73_",""),$M$3:$O$75,ROW(B15)-ROW($M$3)+1,FALSE)&IF(ISBLANK(HLOOKUP(SUBSTITUTE(SUBSTITUTE(SUBSTITUTE(SUBSTITUTE(SUBSTITUTE(VCBW,"AMR_",""),"EVS_",""),"SO3_",""),"SO68_",""),"SO73_",""),$P$3:$R$75,ROW(B15)-ROW($P$3)+1,FALSE)), ""," / "&HLOOKUP(SUBSTITUTE(SUBSTITUTE(SUBSTITUTE(SUBSTITUTE(SUBSTITUTE(VCBW,"AMR_",""),"EVS_",""),"SO3_",""),"SO68_",""),"SO73_",""),$P$3:$R$75,ROW(B15)-ROW($P$3)+1,FALSE)) -> 5.2.2a / 7.2.2.3 | C15: RLR in noise | D15: max vol. | E15: =HLOOKUP(IF(OR("GSM"=Network,"WCDMA"=Network),"UMTS",IF(OR("VoLTE"=Network,"VoNR"=Network,"VoWiFi"=Network),"VoIMS",Network))&" "&VCBW,$T$3:$AF$75,ROW(E15)-ROW($T$3)+1,FALSE) -> -13 | F15: =HLOOKUP(IF(OR("GSM"=Network,"WCDMA"=Network),"UMTS",IF(OR("VoLTE"=Network,"VoNR"=Network,"VoWiFi"=Network),"VoIMS",Network))&" "&VCBW,$AG$3:$AS$75,ROW(E15)-ROW($AG$3)+1,FALSE) -> -10 | G15: dB | H15: 1 | J15: × | K15: × | M15: 5.2.2a | N15: 6.2.2a | O15: 7.2.2a | P15: 7.2.2.3 | Q15: 8.2.2.3 | R15: 9.2.2.3 | T15: -13 | U15: -13 | V15: -13 | W15: -13 | X15: -13 | Y15: -13 | Z15: -13 | AA15: -13 | AB15: -13 | AC15: -13 | AD15: -13 | AE15: -13 | AF15: -13 | AG15: -10 | AH15: -10 | AI15: -10 | AJ15: -10 | AK15: -10 | AL15: -10 | AM15: -10 | AN15: -10 | AO15: -10 | AP15: -10 | AQ15: -10 | AR15: -10 | AS15: -10
A16: Idle channel noise | B16: =HLOOKUP(SUBSTITUTE(SUBSTITUTE(SUBSTITUTE(SUBSTITUTE(SUBSTITUTE(VCBW,"AMR_",""),"EVS_",""),"SO3_",""),"SO68_",""),"SO73_",""),$M$3:$O$75,ROW(B16)-ROW($M$3)+1,FALSE)&IF(ISBLANK(HLOOKUP(SUBSTITUTE(SUBSTITUTE(SUBSTITUTE(SUBSTITUTE(SUBSTITUTE(VCBW,"AMR_",""),"EVS_",""),"SO3_",""),"SO68_",""),"SO73_",""),$P$3:$R$75,ROW(B16)-ROW($P$3)+1,FALSE)), ""," / "&HLOOKUP(SUBSTITUTE(SUBSTITUTE(SUBSTITUTE(SUBSTITUTE(SUBSTITUTE(VCBW,"AMR_",""),"EVS_",""),"SO3_",""),"SO68_",""),"SO73_",""),$P$3:$R$75,ROW(B16)-ROW($P$3)+1,FALSE)) -> 5.3.1 / 7.3.1 | C16: Sending | E16: =HLOOKUP(IF(OR("GSM"=Network,"WCDMA"=Network),"UMTS",IF(OR("VoLTE"=Network,"VoNR"=Network,"VoWiFi"=Network),"VoIMS",Network))&" "&VCBW,$T$3:$AF$75,ROW(E16)-ROW($T$3)+1,FALSE) -> N/A | F16: =HLOOKUP(IF(OR("GSM"=Network,"WCDMA"=Network),"UMTS",IF(OR("VoLTE"=Network,"VoNR"=Network,"VoWiFi"=Network),"VoIMS",Network))&" "&VCBW,$AG$3:$AS$75,ROW(E16)-ROW($AG$3)+1,FALSE) -> -64 | G16: dBm0p | H16: 1 | M16: 5.3.1 | N16: 6.3.1 | O16: 7.3.1 | P16: 7.3.1 | Q16: 8.3.1 | R16: 9.3.1 | T16: N/A | U16: N/A | V16: N/A | W16: N/A | X16: N/A | Y16: N/A | Z16: N/A | AA16: N/A | AB16: N/A | AC16: N/A | AD16: N/A | AE16: N/A | AF16: N/A | AG16: -64 | AH16: -64 | AI16: -64 | AJ16: -64 | AK16: -64 | AL16: -64 | AM16: -64 | AN16: -64 | AO16: -64 | AP16: -64 | AQ16: -64 | AR16: -64 | AS16: -64
B17: =HLOOKUP(SUBSTITUTE(SUBSTITUTE(SUBSTITUTE(SUBSTITUTE(SUBSTITUTE(VCBW,"AMR_",""),"EVS_",""),"SO3_",""),"SO68_",""),"SO73_",""),$M$3:$O$75,ROW(B17)-ROW($M$3)+1,FALSE)&IF(ISBLANK(HLOOKUP(SUBSTITUTE(SUBSTITUTE(SUBSTITUTE(SUBSTITUTE(SUBSTITUTE(VCBW,"AMR_",""),"EVS_",""),"SO3_",""),"SO68_",""),"SO73_",""),$P$3:$R$75,ROW(B17)-ROW($P$3)+1,FALSE)), ""," / "&HLOOKUP(SUBSTITUTE(SUBSTITUTE(SUBSTITUTE(SUBSTITUTE(SUBSTITUTE(VCBW,"AMR_",""),"EVS_",""),"SO3_",""),"SO68_",""),"SO73_",""),$P$3:$R$75,ROW(B17)-ROW($P$3)+1,FALSE)) -> 5.3.1 / 7.3.1 | D17: Single Frequency | E17: =HLOOKUP(IF(OR("GSM"=Network,"WCDMA"=Network),"UMTS",IF(OR("VoLTE"=Network,"VoNR"=Network,"VoWiFi"=Network),"VoIMS",Network))&" "&VCBW,$T$3:$AF$75,ROW(E17)-ROW($T$3)+1,FALSE) -> N/A | F17: =HLOOKUP(IF(OR("GSM"=Network,"WCDMA"=Network),"UMTS",IF(OR("VoLTE"=Network,"VoNR"=Network,"VoWiFi"=Network),"VoIMS",Network))&" "&VCBW,$AG$3:$AS$75,ROW(E17)-ROW($AG$3)+1,FALSE) -> -74 | G17: dBm0p | H17: 1 | M17: 5.3.1 | N17: 6.3.1 | O17: 7.3.1 | P17: 7.3.1 | Q17: 8.3.1 | R17: 9.3.1 | T17: N/A | U17: N/A | V17: N/A | W17: N/A | X17: N/A | Y17: N/A | Z17: N/A | AA17: N/A | AB17: N/A | AC17: N/A | AD17: N/A | AE17: N/A | AF17: N/A | AG17: -74 | AH17: -74 | AI17: -74 | AJ17: -74 | AK17: -74 | AL17: -74 | AM17: -74 | AN17: -74 | AO17: -74 | AP17: -74 | AQ17: -74 | AR17: -74 | AS17: -74
B18: =HLOOKUP(SUBSTITUTE(SUBSTITUTE(SUBSTITUTE(SUBSTITUTE(SUBSTITUTE(VCBW,"AMR_",""),"EVS_",""),"SO3_",""),"SO68_",""),"SO73_",""),$M$3:$O$75,ROW(B18)-ROW($M$3)+1,FALSE)&IF(ISBLANK(HLOOKUP(SUBSTITUTE(SUBSTITUTE(SUBSTITUTE(SUBSTITUTE(SUBSTITUTE(VCBW,"AMR_",""),"EVS_",""),"SO3_",""),"SO68_",""),"SO73_",""),$P$3:$R$75,ROW(B18)-ROW($P$3)+1,FALSE)), ""," / "&HLOOKUP(SUBSTITUTE(SUBSTITUTE(SUBSTITUTE(SUBSTITUTE(SUBSTITUTE(VCBW,"AMR_",""),"EVS_",""),"SO3_",""),"SO68_",""),"SO73_",""),$P$3:$R$75,ROW(B18)-ROW($P$3)+1,FALSE)) -> 5.3.2 / 7.3.2 | C18: Receiving | D18: max vol. | E18: =HLOOKUP(IF(OR("GSM"=Network,"WCDMA"=Network),"UMTS",IF(OR("VoLTE"=Network,"VoNR"=Network,"VoWiFi"=Network),"VoIMS",Network))&" "&VCBW,$T$3:$AF$75,ROW(E18)-ROW($T$3)+1,FALSE) -> N/A | F18: =HLOOKUP(IF(OR("GSM"=Network,"WCDMA"=Network),"UMTS",IF(OR("VoLTE"=Network,"VoNR"=Network,"VoWiFi"=Network),"VoIMS",Network))&" "&VCBW,$AG$3:$AS$75,ROW(E18)-ROW($AG$3)+1,FALSE) -> -54 | G18: dBPa(A) | H18: 1 | M18: 5.3.2 | N18: 6.3.2 | O18: 7.3.2 | P18: 7.3.2 | Q18: 8.3.2 | R18: 9.3.2 | T18: N/A | U18: N/A | V18: N/A | W18: N/A | X18: N/A | Y18: N/A | Z18: N/A | AA18: N/A | AB18: N/A | AC18: N/A | AD18: N/A | AE18: N/A | AF18: N/A | AG18: -54 | AH18: -54 | AI18: -54 | AJ18: -54 | AK18: -54 | AL18: -54 | AM18: -54 | AN18: -54 | AO18: -54 | AP18: -54 | AQ18: -54 | AR18: -54 | AS18: -54
B19: =HLOOKUP(SUBSTITUTE(SUBSTITUTE(SUBSTITUTE(SUBSTITUTE(SUBSTITUTE(VCBW,"AMR_",""),"EVS_",""),"SO3_",""),"SO68_",""),"SO73_",""),$M$3:$O$75,ROW(B19)-ROW($M$3)+1,FALSE)&IF(ISBLANK(HLOOKUP(SUBSTITUTE(SUBSTITUTE(SUBSTITUTE(SUBSTITUTE(SUBSTITUTE(VCBW,"AMR_",""),"EVS_",""),"SO3_",""),"SO68_",""),"SO73_",""),$P$3:$R$75,ROW(B19)-ROW($P$3)+1,FALSE)), ""," / "&HLOOKUP(SUBSTITUTE(SUBSTITUTE(SUBSTITUTE(SUBSTITUTE(SUBSTITUTE(VCBW,"AMR_",""),"EVS_",""),"SO3_",""),"SO68_",""),"SO73_",""),$P$3:$R$75,ROW(B19)-ROW($P$3)+1,FALSE)) -> 5.3.2 / 7.3.2 | D19: nom vol. | E19: =HLOOKUP(IF(OR("GSM"=Network,"WCDMA"=Network),"UMTS",IF(OR("VoLTE"=Network,"VoNR"=Network,"VoWiFi"=Network),"VoIMS",Network))&" "&VCBW,$T$3:$AF$75,ROW(E19)-ROW($T$3)+1,FALSE) -> N/A | F19: =HLOOKUP(IF(OR("GSM"=Network,"WCDMA"=Network),"UMTS",IF(OR("VoLTE"=Network,"VoNR"=Network,"VoWiFi"=Network),"VoIMS",Network))&" "&VCBW,$AG$3:$AS$75,ROW(E19)-ROW($AG$3)+1,FALSE) -> -57 | G19: dBPa(A) | H19: 1 | M19: 5.3.2 | N19: 6.3.2 | O19: 7.3.2 | P19: 7.3.2 | Q19: 8.3.2 | R19: 9.3.2 | T19: N/A | U19: N/A | V19: N/A | W19: N/A | X19: N/A | Y19: N/A | Z19: N/A | AA19: N/A | AB19: N/A | AC19: N/A | AD19: N/A | AE19: N/A | AF19: N/A | AG19: -57 | AH19: -57 | AI19: -57 | AJ19: -57 | AK19: -57 | AL19: -57 | AM19: -57 | AN19: -57 | AO19: -57 | AP19: -57 | AQ19: -57 | AR19: -57 | AS19: -57
B20: =HLOOKUP(SUBSTITUTE(SUBSTITUTE(SUBSTITUTE(SUBSTITUTE(SUBSTITUTE(VCBW,"AMR_",""),"EVS_",""),"SO3_",""),"SO68_",""),"SO73_",""),$M$3:$O$75,ROW(B20)-ROW($M$3)+1,FALSE)&IF(ISBLANK(HLOOKUP(SUBSTITUTE(SUBSTITUTE(SUBSTITUTE(SUBSTITUTE(SUBSTITUTE(VCBW,"AMR_",""),"EVS_",""),"SO3_",""),"SO68_",""),"SO73_",""),$P$3:$R$75,ROW(B20)-ROW($P$3)+1,FALSE)), ""," / "&HLOOKUP(SUBSTITUTE(SUBSTITUTE(SUBSTITUTE(SUBSTITUTE(SUBSTITUTE(VCBW,"AMR_",""),"EVS_",""),"SO3_",""),"SO68_",""),"SO73_",""),$P$3:$R$75,ROW(B20)-ROW($P$3)+1,FALSE)) -> 5.3.2 / 7.3.2 | D20: Single Frequency | E20: =HLOOKUP(IF(OR("GSM"=Network,"WCDMA"=Network),"UMTS",IF(OR("VoLTE"=Network,"VoNR"=Network,"VoWiFi"=Network),"VoIMS",Network))&" "&VCBW,$T$3:$AF$75,ROW(E20)-ROW($T$3)+1,FALSE) -> N/A | F20: =HLOOKUP(IF(OR("GSM"=Network,"WCDMA"=Network),"UMTS",IF(OR("VoLTE"=Network,"VoNR"=Network,"VoWiFi"=Network),"VoIMS",Network))&" "&VCBW,$AG$3:$AS$75,ROW(E20)-ROW($AG$3)+1,FALSE) -> -60 | G20: dBPa(A) | H20: 1 | M20: 5.3.2 | N20: 6.3.2 | O20: 7.3.2 | P20: 7.3.2 | Q20: 8.3.2 | R20: 9.3.2 | T20: N/A | U20: N/A | V20: N/A | W20: N/A | X20: N/A | Y20: N/A | Z20: N/A | AA20: N/A | AB20: N/A | AC20: N/A | AD20: N/A | AE20: N/A | AF20: N/A | AG20: -60 | AH20: -60 | AI20: -60 | AJ20: -60 | AK20: -60 | AL20: -60 | AM20: -60 | AN20: -60 | AO20: -60 | AP20: -60 | AQ20: -60 | AR20: -60 | AS20: -60
A21: Sensitivity/frequency characteristics | B21: =HLOOKUP(SUBSTITUTE(SUBSTITUTE(SUBSTITUTE(SUBSTITUTE(SUBSTITUTE(VCBW,"AMR_",""),"EVS_",""),"SO3_",""),"SO68_",""),"SO73_",""),$M$3:$O$75,ROW(B21)-ROW($M$3)+1,FALSE)&IF(ISBLANK(HLOOKUP(SUBSTITUTE(SUBSTITUTE(SUBSTITUTE(SUBSTITUTE(SUBSTITUTE(VCBW,"AMR_",""),"EVS_",""),"SO3_",""),"SO68_",""),"SO73_",""),$P$3:$R$75,ROW(B21)-ROW($P$3)+1,FALSE)), ""," / "&HLOOKUP(SUBSTITUTE(SUBSTITUTE(SUBSTITUTE(SUBSTITUTE(SUBSTITUTE(VCBW,"AMR_",""),"EVS_",""),"SO3_",""),"SO68_",""),"SO73_",""),$P$3:$R$75,ROW(B21)-ROW($P$3)+1,FALSE)) -> 5.4.1 / 7.4.1 | C21: Sending | E21: =HLOOKUP(IF(OR("GSM"=Network,"WCDMA"=Network),"UMTS",IF(OR("VoLTE"=Network,"VoNR"=Network,"VoWiFi"=Network),"VoIMS",Network))&" "&VCBW,$T$3:$AF$75,ROW(E21)-ROW($T$3)+1,FALSE) -> 2 | F21: =HLOOKUP(IF(OR("GSM"=Network,"WCDMA"=Network),"UMTS",IF(OR("VoLTE"=Network,"VoNR"=Network,"VoWiFi"=Network),"VoIMS",Network))&" "&VCBW,$AG$3:$AS$75,ROW(E21)-ROW($AG$3)+1,FALSE) -> N/A | G21: dB | H21: 1 | M21: 5.4.1 | N21: 6.4.1 | O21: 7.4.1 | P21: 7.4.1 | Q21: 8.4.1 | R21: 9.4.1 | T21: 2 | U21: 2 | V21: 2 | W21: 2 | X21: 2 | Y21: 2 | Z21: 2 | AA21: 2 | AB21: 2 | AC21: 2 | AD21: 2 | AE21: 2 | AF21: 2 | AG21: N/A | AH21: N/A | AI21: N/A | AJ21: N/A | AK21: N/A | AL21: N/A | AM21: N/A | AN21: N/A | AO21: N/A | AP21: N/A | AQ21: N/A | AR21: N/A | AS21: N/A
B22: =HLOOKUP(SUBSTITUTE(SUBSTITUTE(SUBSTITUTE(SUBSTITUTE(SUBSTITUTE(VCBW,"AMR_",""),"EVS_",""),"SO3_",""),"SO68_",""),"SO73_",""),$M$3:$O$75,ROW(B22)-ROW($M$3)+1,FALSE)&IF(ISBLANK(HLOOKUP(SUBSTITUTE(SUBSTITUTE(SUBSTITUTE(SUBSTITUTE(SUBSTITUTE(VCBW,"AMR_",""),"EVS_",""),"SO3_",""),"SO68_",""),"SO73_",""),$P$3:$R$75,ROW(B22)-ROW($P$3)+1,FALSE)), ""," / "&HLOOKUP(SUBSTITUTE(SUBSTITUTE(SUBSTITUTE(SUBSTITUTE(SUBSTITUTE(VCBW,"AMR_",""),"EVS_",""),"SO3_",""),"SO68_",""),"SO73_",""),$P$3:$R$75,ROW(B22)-ROW($P$3)+1,FALSE)) -> 5.4.2 / 7.4.2 | C22: Receiving | D22: max vol. | E22: =HLOOKUP(IF(OR("GSM"=Network,"WCDMA"=Network),"UMTS",IF(OR("VoLTE"=Network,"VoNR"=Network,"VoWiFi"=Network),"VoIMS",Network))&" "&VCBW,$T$3:$AF$75,ROW(E22)-ROW($T$3)+1,FALSE) -> 1 | F22: =HLOOKUP(IF(OR("GSM"=Network,"WCDMA"=Network),"UMTS",IF(OR("VoLTE"=Network,"VoNR"=Network,"VoWiFi"=Network),"VoIMS",Network))&" "&VCBW,$AG$3:$AS$75,ROW(E22)-ROW($AG$3)+1,FALSE) -> N/A | G22: dB | H22: 1 | M22: 5.4.2 | N22: 6.4.1 | O22: 7.4.1 | P22: 7.4.2 | Q22: 8.4.2 | R22: 9.4.2 | T22: 1 | U22: 1 | V22: 1 | W22: 1 | X22: 1 | Y22: 1 | Z22: 1 | AA22: 1 | AB22: 1 | AC22: 1 | AD22: 1 | AE22: 1 | AF22: 1 | AG22: N/A | AH22: N/A | AI22: N/A | AJ22: N/A | AK22: N/A | AL22: N/A | AM22: N/A | AN22: N/A | AO22: N/A | AP22: N/A | AQ22: N/A | AR22: N/A | AS22: N/A
B23: =HLOOKUP(SUBSTITUTE(SUBSTITUTE(SUBSTITUTE(SUBSTITUTE(SUBSTITUTE(VCBW,"AMR_",""),"EVS_",""),"SO3_",""),"SO68_",""),"SO73_",""),$M$3:$O$75,ROW(B23)-ROW($M$3)+1,FALSE)&IF(ISBLANK(HLOOKUP(SUBSTITUTE(SUBSTITUTE(SUBSTITUTE(SUBSTITUTE(SUBSTITUTE(VCBW,"AMR_",""),"EVS_",""),"SO3_",""),"SO68_",""),"SO73_",""),$P$3:$R$75,ROW(B23)-ROW($P$3)+1,FALSE)), ""," / "&HLOOKUP(SUBSTITUTE(SUBSTITUTE(SUBSTITUTE(SUBSTITUTE(SUBSTITUTE(VCBW,"AMR_",""),"EVS_",""),"SO3_",""),"SO68_",""),"SO73_",""),$P$3:$R$75,ROW(B23)-ROW($P$3)+1,FALSE)) -> 5.4.2 / 7.4.2 | D23: nom vol. 1/12Oct | E23: =HLOOKUP(IF(OR("GSM"=Network,"WCDMA"=Network),"UMTS",IF(OR("VoLTE"=Network,"VoNR"=Network,"VoWiFi"=Network),"VoIMS",Network))&" "&VCBW,$T$3:$AF$75,ROW(E23)-ROW($T$3)+1,FALSE) -> 2 | F23: =HLOOKUP(IF(OR("GSM"=Network,"WCDMA"=Network),"UMTS",IF(OR("VoLTE"=Network,"VoNR"=Network,"VoWiFi"=Network),"VoIMS",Network))&" "&VCBW,$AG$3:$AS$75,ROW(E23)-ROW($AG$3)+1,FALSE) -> N/A | G23: dB | H23: 1 | M23: 5.4.2 | N23: 6.4.2 | O23: 7.4.2.1 | P23: 7.4.2 | Q23: 8.4.2 | R23: 9.4.2 | T23: 2 | U23: 2 | V23: 2 | W23: 2 | X23: 2 | Y23: 2 | Z23: 1 | AA23: 2 | AB23: 2 | AC23: 2 | AD23: 2 | AE23: 2 | AF23: 1 | AG23: N/A | AH23: N/A | AI23: N/A | AJ23: N/A | AK23: N/A | AL23: N/A | AM23: N/A | AN23: N/A | AO23: N/A | AP23: N/A | AQ23: N/A | AR23: N/A | AS23: N/A
B24: =HLOOKUP(SUBSTITUTE(SUBSTITUTE(SUBSTITUTE(SUBSTITUTE(SUBSTITUTE(VCBW,"AMR_",""),"EVS_",""),"SO3_",""),"SO68_",""),"SO73_",""),$M$3:$O$75,ROW(B24)-ROW($M$3)+1,FALSE)&IF(ISBLANK(HLOOKUP(SUBSTITUTE(SUBSTITUTE(SUBSTITUTE(SUBSTITUTE(SUBSTITUTE(VCBW,"AMR_",""),"EVS_",""),"SO3_",""),"SO68_",""),"SO73_",""),$P$3:$R$75,ROW(B24)-ROW($P$3)+1,FALSE)), ""," / "&HLOOKUP(SUBSTITUTE(SUBSTITUTE(SUBSTITUTE(SUBSTITUTE(SUBSTITUTE(VCBW,"AMR_",""),"EVS_",""),"SO3_",""),"SO68_",""),"SO73_",""),$P$3:$R$75,ROW(B24)-ROW($P$3)+1,FALSE)) -> × / 7.4.2 | D24: nom vol. 1/3Oct | E24: =HLOOKUP(IF(OR("GSM"=Network,"WCDMA"=Network),"UMTS",IF(OR("VoLTE"=Network,"VoNR"=Network,"VoWiFi"=Network),"VoIMS",Network))&" "&VCBW,$T$3:$AF$75,ROW(E24)-ROW($T$3)+1,FALSE) -> N/A | F24: =HLOOKUP(IF(OR("GSM"=Network,"WCDMA"=Network),"UMTS",IF(OR("VoLTE"=Network,"VoNR"=Network,"VoWiFi"=Network),"VoIMS",Network))&" "&VCBW,$AG$3:$AS$75,ROW(E24)-ROW($AG$3)+1,FALSE) -> N/A | G24: dB | H24: 1 | M24: × | N24: × | O24: 7.4.2.1 | P24: 7.4.2 | Q24: 8.4.2 | R24: 9.4.2 | T24: N/A | U24: N/A | V24: N/A | W24: N/A | X24: N/A | Y24: N/A | Z24: 1 | AA24: N/A | AB24: N/A | AC24: N/A | AD24: N/A | AE24: N/A | AF24: 1 | AG24: N/A | AH24: N/A | AI24: N/A | AJ24: N/A | AK24: N/A | AL24: N/A | AM24: N/A | AN24: N/A | AO24: N/A | AP24: N/A | AQ24: N/A | AR24: N/A | AS24: N/A
B25: =HLOOKUP(SUBSTITUTE(SUBSTITUTE(SUBSTITUTE(SUBSTITUTE(SUBSTITUTE(VCBW,"AMR_",""),"EVS_",""),"SO3_",""),"SO68_",""),"SO73_",""),$M$3:$O$75,ROW(B25)-ROW($M$3)+1,FALSE)&IF(ISBLANK(HLOOKUP(SUBSTITUTE(SUBSTITUTE(SUBSTITUTE(SUBSTITUTE(SUBSTITUTE(VCBW,"AMR_",""),"EVS_",""),"SO3_",""),"SO68_",""),"SO73_",""),$P$3:$R$75,ROW(B25)-ROW($P$3)+1,FALSE)), ""," / "&HLOOKUP(SUBSTITUTE(SUBSTITUTE(SUBSTITUTE(SUBSTITUTE(SUBSTITUTE(VCBW,"AMR_",""),"EVS_",""),"SO3_",""),"SO68_",""),"SO73_",""),$P$3:$R$75,ROW(B25)-ROW($P$3)+1,FALSE)) -> 5.4.2 / 7.4.2 | D25: min vol. | E25: =HLOOKUP(IF(OR("GSM"=Network,"WCDMA"=Network),"UMTS",IF(OR("VoLTE"=Network,"VoNR"=Network,"VoWiFi"=Network),"VoIMS",Network))&" "&VCBW,$T$3:$AF$75,ROW(E25)-ROW($T$3)+1,FALSE) -> 2 | F25: =HLOOKUP(IF(OR("GSM"=Network,"WCDMA"=Network),"UMTS",IF(OR("VoLTE"=Network,"VoNR"=Network,"VoWiFi"=Network),"VoIMS",Network))&" "&VCBW,$AG$3:$AS$75,ROW(E25)-ROW($AG$3)+1,FALSE) -> N/A | G25: dB | H25: 1 | M25: 5.4.2 | N25: 6.4.2 | O25: 7.4.2.1 | P25: 7.4.2 | Q25: 8.4.2 | R25: 9.4.2 | T25: 2 | U25: 2 | V25: 2 | W25: 2 | X25: 2 | Y25: 2 | Z25: 2 | AA25: 2 | AB25: 2 | AC25: 2 | AD25: 2 | AE25: 2 | AF25: 2 | AG25: N/A | AH25: N/A | AI25: N/A | AJ25: N/A | AK25: N/A | AL25: N/A | AM25: N/A | AN25: N/A | AO25: N/A | AP25: N/A | AQ25: N/A | AR25: N/A | AS25: N/A
A26: Sidetone characteristics | B26: =HLOOKUP(SUBSTITUTE(SUBSTITUTE(SUBSTITUTE(SUBSTITUTE(SUBSTITUTE(VCBW,"AMR_",""),"EVS_",""),"SO3_",""),"SO68_",""),"SO73_",""),$M$3:$O$75,ROW(B26)-ROW($M$3)+1,FALSE)&IF(ISBLANK(HLOOKUP(SUBSTITUTE(SUBSTITUTE(SUBSTITUTE(SUBSTITUTE(SUBSTITUTE(VCBW,"AMR_",""),"EVS_",""),"SO3_",""),"SO68_",""),"SO73_",""),$P$3:$R$75,ROW(B26)-ROW($P$3)+1,FALSE)), ""," / "&HLOOKUP(SUBSTITUTE(SUBSTITUTE(SUBSTITUTE(SUBSTITUTE(SUBSTITUTE(VCBW,"AMR_",""),"EVS_",""),"SO3_",""),"SO68_",""),"SO73_",""),$P$3:$R$75,ROW(B26)-ROW($P$3)+1,FALSE)) -> 5.5.1 / 7.5.1 | C26: STMR | D26: max vol. | E26: =HLOOKUP(IF(OR("GSM"=Network,"WCDMA"=Network),"UMTS",IF(OR("VoLTE"=Network,"VoNR"=Network,"VoWiFi"=Network),"VoIMS",Network))&" "&VCBW,$T$3:$AF$75,ROW(E26)-ROW($T$3)+1,FALSE) -> 10 | F26: =HLOOKUP(IF(OR("GSM"=Network,"WCDMA"=Network),"UMTS",IF(OR("VoLTE"=Network,"VoNR"=Network,"VoWiFi"=Network),"VoIMS",Network))&" "&VCBW,$AG$3:$AS$75,ROW(E26)-ROW($AG$3)+1,FALSE) -> 23 | G26: dB | H26: 3 | M26: 5.5.1 | N26: 6.5.1 | O26: 7.5.1 | P26: 7.5.1 | Q26: 8.5.1 | R26: 9.5.1 | T26: 10 | U26: 10 | V26: 10 | W26: 10 | X26: 10 | Y26: 10 | Z26: 10 | AA26: 10 | AB26: 10 | AC26: 10 | AD26: 10 | AE26: 10 | AF26: 10 | AG26: 23 | AH26: 23 | AI26: 23 | AJ26: 23 | AK26: 23 | AL26: 23 | AM26: 23 | AN26: 23 | AO26: 23 | AP26: 23 | AQ26: 23 | AR26: 23 | AS26: 23
B27: =HLOOKUP(SUBSTITUTE(SUBSTITUTE(SUBSTITUTE(SUBSTITUTE(SUBSTITUTE(VCBW,"AMR_",""),"EVS_",""),"SO3_",""),"SO68_",""),"SO73_",""),$M$3:$O$75,ROW(B27)-ROW($M$3)+1,FALSE)&IF(ISBLANK(HLOOKUP(SUBSTITUTE(SUBSTITUTE(SUBSTITUTE(SUBSTITUTE(SUBSTITUTE(VCBW,"AMR_",""),"EVS_",""),"SO3_",""),"SO68_",""),"SO73_",""),$P$3:$R$75,ROW(B27)-ROW($P$3)+1,FALSE)), ""," / "&HLOOKUP(SUBSTITUTE(SUBSTITUTE(SUBSTITUTE(SUBSTITUTE(SUBSTITUTE(VCBW,"AMR_",""),"EVS_",""),"SO3_",""),"SO68_",""),"SO73_",""),$P$3:$R$75,ROW(B27)-ROW($P$3)+1,FALSE)) -> 5.5.1 / 7.5.1 | D27: mon. vol. | E27: =HLOOKUP(IF(OR("GSM"=Network,"WCDMA"=Network),"UMTS",IF(OR("VoLTE"=Network,"VoNR"=Network,"VoWiFi"=Network),"VoIMS",Network))&" "&VCBW,$T$3:$AF$75,ROW(E27)-ROW($T$3)+1,FALSE) -> 15 | F27: =HLOOKUP(IF(OR("GSM"=Network,"WCDMA"=Network),"UMTS",IF(OR("VoLTE"=Network,"VoNR"=Network,"VoWiFi"=Network),"VoIMS",Network))&" "&VCBW,$AG$3:$AS$75,ROW(E27)-ROW($AG$3)+1,FALSE) -> 23 | G27: dB | H27: 3 | M27: 5.5.1 | N27: 6.5.1 | O27: 7.5.1 | P27: 7.5.1 | Q27: 8.5.1 | R27: 9.5.1 | T27: 15 | U27: 15 | V27: 15 | W27: 15 | X27: 15 | Y27: 15 | Z27: 15 | AA27: 15 | AB27: 15 | AC27: 15 | AD27: 15 | AE27: 15 | AF27: 15 | AG27: 23 | AH27: 23 | AI27: 23 | AJ27: 23 | AK27: 23 | AL27: 23 | AM27: 23 | AN27: 23 | AO27: 23 | AP27: 23 | AQ27: 23 | AR27: 23 | AS27: 23
B28: =HLOOKUP(SUBSTITUTE(SUBSTITUTE(SUBSTITUTE(SUBSTITUTE(SUBSTITUTE(VCBW,"AMR_",""),"EVS_",""),"SO3_",""),"SO68_",""),"SO73_",""),$M$3:$O$75,ROW(B28)-ROW($M$3)+1,FALSE)&IF(ISBLANK(HLOOKUP(SUBSTITUTE(SUBSTITUTE(SUBSTITUTE(SUBSTITUTE(SUBSTITUTE(VCBW,"AMR_",""),"EVS_",""),"SO3_",""),"SO68_",""),"SO73_",""),$P$3:$R$75,ROW(B28)-ROW($P$3)+1,FALSE)), ""," / "&HLOOKUP(SUBSTITUTE(SUBSTITUTE(SUBSTITUTE(SUBSTITUTE(SUBSTITUTE(VCBW,"AMR_",""),"EVS_",""),"SO3_",""),"SO68_",""),"SO73_",""),$P$3:$R$75,ROW(B28)-ROW($P$3)+1,FALSE)) -> 5.5.1 / 7.5.1 | D28: min vol. | E28: =HLOOKUP(IF(OR("GSM"=Network,"WCDMA"=Network),"UMTS",IF(OR("VoLTE"=Network,"VoNR"=Network,"VoWiFi"=Network),"VoIMS",Network))&" "&VCBW,$T$3:$AF$75,ROW(E28)-ROW($T$3)+1,FALSE) -> 10 | F28: =HLOOKUP(IF(OR("GSM"=Network,"WCDMA"=Network),"UMTS",IF(OR("VoLTE"=Network,"VoNR"=Network,"VoWiFi"=Network),"VoIMS",Network))&" "&VCBW,$AG$3:$AS$75,ROW(E28)-ROW($AG$3)+1,FALSE) -> 23 | G28: dB | H28: 3 | M28: 5.5.1 | N28: 6.5.1 | O28: 7.5.1 | P28: 7.5.1 | Q28: 8.5.1 | R28: 9.5.1 | T28: 10 | U28: 10 | V28: 10 | W28: 10 | X28: 10 | Y28: 10 | Z28: 10 | AA28: 10 | AB28: 10 | AC28: 10 | AD28: 10 | AE28: 10 | AF28: 10 | AG28: 23 | AH28: 23 | AI28: 23 | AJ28: 23 | AK28: 23 | AL28: 23 | AM28: 23 | AN28: 23 | AO28: 23 | AP28: 23 | AQ28: 23 | AR28: 23 | AS28: 23
B29: =HLOOKUP(SUBSTITUTE(SUBSTITUTE(SUBSTITUTE(SUBSTITUTE(SUBSTITUTE(VCBW,"AMR_",""),"EVS_",""),"SO3_",""),"SO68_",""),"SO73_",""),$M$3:$O$75,ROW(B29)-ROW($M$3)+1,FALSE)&IF(ISBLANK(HLOOKUP(SUBSTITUTE(SUBSTITUTE(SUBSTITUTE(SUBSTITUTE(SUBSTITUTE(VCBW,"AMR_",""),"EVS_",""),"SO3_",""),"SO68_",""),"SO73_",""),$P$3:$R$75,ROW(B29)-ROW($P$3)+1,FALSE)), ""," / "&HLOOKUP(SUBSTITUTE(SUBSTITUTE(SUBSTITUTE(SUBSTITUTE(SUBSTITUTE(VCBW,"AMR_",""),"EVS_",""),"SO3_",""),"SO68_",""),"SO73_",""),$P$3:$R$75,ROW(B29)-ROW($P$3)+1,FALSE)) -> 5.5.2 / 7.5.4 | C29: Delay | E29: =HLOOKUP(IF(OR("GSM"=Network,"WCDMA"=Network),"UMTS",IF(OR("VoLTE"=Network,"VoNR"=Network,"VoWiFi"=Network),"VoIMS",Network))&" "&VCBW,$T$3:$AF$75,ROW(E29)-ROW($T$3)+1,FALSE) -> 0 | F29: =HLOOKUP(IF(OR("GSM"=Network,"WCDMA"=Network),"UMTS",IF(OR("VoLTE"=Network,"VoNR"=Network,"VoWiFi"=Network),"VoIMS",Network))&" "&VCBW,$AG$3:$AS$75,ROW(E29)-ROW($AG$3)+1,FALSE) -> 5 | G29: ms | H29: 1 | M29: 5.5.2 | N29: 6.5.2 | O29: 7.5.2 | P29: 7.5.4 | Q29: 8.5.4 | R29: 9.5.4 | T29: 0 | U29: 0 | V29: 0 | W29: 0 | X29: 0 | Y29: 0 | Z29: 0 | AA29: 0 | AB29: 0 | AC29: 0 | AD29: 0 | AE29: 0 | AF29: 0 | AG29: 5 | AH29: 5 | AI29: 5 | AJ29: 5 | AK29: 5 | AL29: 5 | AM29: 5 | AN29: 5 | AO29: 5 | AP29: 5 | AQ29: 5 | AR29: 5 | AS29: 5
A30: Stability loss | B30: =HLOOKUP(SUBSTITUTE(SUBSTITUTE(SUBSTITUTE(SUBSTITUTE(SUBSTITUTE(VCBW,"AMR_",""),"EVS_",""),"SO3_",""),"SO68_",""),"SO73_",""),$M$3:$O$75,ROW(B30)-ROW($M$3)+1,FALSE)&IF(ISBLANK(HLOOKUP(SUBSTITUTE(SUBSTITUTE(SUBSTITUTE(SUBSTITUTE(SUBSTITUTE(VCBW,"AMR_",""),"EVS_",""),"SO3_",""),"SO68_",""),"SO73_",""),$P$3:$R$75,ROW(B30)-ROW($P$3)+1,FALSE)), ""," / "&HLOOKUP(SUBSTITUTE(SUBSTITUTE(SUBSTITUTE(SUBSTITUTE(SUBSTITUTE(VCBW,"AMR_",""),"EVS_",""),"SO3_",""),"SO68_",""),"SO73_",""),$P$3:$R$75,ROW(B30)-ROW($P$3)+1,FALSE)) -> 5.6 / 7.6 | D30: max vol. | E30: =HLOOKUP(IF(OR("GSM"=Network,"WCDMA"=Network),"UMTS",IF(OR("VoLTE"=Network,"VoNR"=Network,"VoWiFi"=Network),"VoIMS",Network))&" "&VCBW,$T$3:$AF$75,ROW(E30)-ROW($T$3)+1,FALSE) -> 6 | F30: =HLOOKUP(IF(OR("GSM"=Network,"WCDMA"=Network),"UMTS",IF(OR("VoLTE"=Network,"VoNR"=Network,"VoWiFi"=Network),"VoIMS",Network))&" "&VCBW,$AG$3:$AS$75,ROW(E30)-ROW($AG$3)+1,FALSE) -> N/A | G30: dB | H30: 1 | M30: 5.6 | N30: 6.6 | O30: 7.6 | P30: 7.6 | Q30: 8.6 | R30: 9.6 | T30: 6 | U30: 6 | V30: 6 | W30: 6 | X30: 6 | Y30: 6 | Z30: 6 | AA30: 6 | AB30: 6 | AC30: 6 | AD30: 6 | AE30: 6 | AF30: 6 | AG30: N/A | AH30: N/A | AI30: N/A | AJ30: N/A | AK30: N/A | AL30: N/A | AM30: N/A | AN30: N/A | AO30: N/A | AP30: N/A | AQ30: N/A | AR30: N/A | AS30: N/A
A31: Acoustic echo control | B31: =HLOOKUP(SUBSTITUTE(SUBSTITUTE(SUBSTITUTE(SUBSTITUTE(SUBSTITUTE(VCBW,"AMR_",""),"EVS_",""),"SO3_",""),"SO68_",""),"SO73_",""),$M$3:$O$75,ROW(B31)-ROW($M$3)+1,FALSE)&IF(ISBLANK(HLOOKUP(SUBSTITUTE(SUBSTITUTE(SUBSTITUTE(SUBSTITUTE(SUBSTITUTE(VCBW,"AMR_",""),"EVS_",""),"SO3_",""),"SO68_",""),"SO73_",""),$P$3:$R$75,ROW(B31)-ROW($P$3)+1,FALSE)), ""," / "&HLOOKUP(SUBSTITUTE(SUBSTITUTE(SUBSTITUTE(SUBSTITUTE(SUBSTITUTE(VCBW,"AMR_",""),"EVS_",""),"SO3_",""),"SO68_",""),"SO73_",""),$P$3:$R$75,ROW(B31)-ROW($P$3)+1,FALSE)) -> 5.7.4 / 7.7.3 | C31: Echo Loss (TCLw) | D31: max vol. | E31: =HLOOKUP(IF(OR("GSM"=Network,"WCDMA"=Network),"UMTS",IF(OR("VoLTE"=Network,"VoNR"=Network,"VoWiFi"=Network),"VoIMS",Network))&" "&VCBW,$T$3:$AF$75,ROW(E31)-ROW($T$3)+1,FALSE) -> 46 | F31: =HLOOKUP(IF(OR("GSM"=Network,"WCDMA"=Network),"UMTS",IF(OR("VoLTE"=Network,"VoNR"=Network,"VoWiFi"=Network),"VoIMS",Network))&" "&VCBW,$AG$3:$AS$75,ROW(E31)-ROW($AG$3)+1,FALSE) -> N/A | G31: dB | H31: 1 | M31: 5.7.4 | N31: 6.7.4 | O31: 7.7.4 | P31: 7.7.3 | Q31: 8.7.3 | R31: 9.7.3 | T31: 46 | U31: 46 | V31: 46 | W31: 46 | X31: 46 | Y31: 46 | Z31: 46 | AA31: 46 | AB31: 46 | AC31: 46 | AD31: 46 | AE31: 46 | AF31: 46 | AG31: N/A | AH31: N/A | AI31: N/A | AJ31: N/A | AK31: N/A | AL31: N/A | AM31: N/A | AN31: N/A | AO31: N/A | AP31: N/A | AQ31: N/A | AR31: N/A | AS31: N/A
B32: =HLOOKUP(SUBSTITUTE(SUBSTITUTE(SUBSTITUTE(SUBSTITUTE(SUBSTITUTE(VCBW,"AMR_",""),"EVS_",""),"SO3_",""),"SO68_",""),"SO73_",""),$M$3:$O$75,ROW(B32)-ROW($M$3)+1,FALSE)&IF(ISBLANK(HLOOKUP(SUBSTITUTE(SUBSTITUTE(SUBSTITUTE(SUBSTITUTE(SUBSTITUTE(VCBW,"AMR_",""),"EVS_",""),"SO3_",""),"SO68_",""),"SO73_",""),$P$3:$R$75,ROW(B32)-ROW($P$3)+1,FALSE)), ""," / "&HLOOKUP(SUBSTITUTE(SUBSTITUTE(SUBSTITUTE(SUBSTITUTE(SUBSTITUTE(VCBW,"AMR_",""),"EVS_",""),"SO3_",""),"SO68_",""),"SO73_",""),$P$3:$R$75,ROW(B32)-ROW($P$3)+1,FALSE)) -> 5.7.4 / 7.7.3 | D32: mon. vol. | E32: =HLOOKUP(IF(OR("GSM"=Network,"WCDMA"=Network),"UMTS",IF(OR("VoLTE"=Network,"VoNR"=Network,"VoWiFi"=Network),"VoIMS",Network))&" "&VCBW,$T$3:$AF$75,ROW(E32)-ROW($T$3)+1,FALSE) -> 55 | F32: =HLOOKUP(IF(OR("GSM"=Network,"WCDMA"=Network),"UMTS",IF(OR("VoLTE"=Network,"VoNR"=Network,"VoWiFi"=Network),"VoIMS",Network))&" "&VCBW,$AG$3:$AS$75,ROW(E32)-ROW($AG$3)+1,FALSE) -> N/A | G32: dB | H32: 1 | M32: 5.7.4 | N32: 6.7.4 | O32: 7.7.4 | P32: 7.7.3 | Q32: 8.7.3 | R32: 9.7.3 | T32: 55 | U32: 55 | V32: 55 | W32: 55 | X32: 55 | Y32: 55 | Z32: 55 | AA32: 55 | AB32: 55 | AC32: 55 | AD32: 55 | AE32: 55 | AF32: 55 | AG32: N/A | AH32: N/A | AI32: N/A | AJ32: N/A | AK32: N/A | AL32: N/A | AM32: N/A | AN32: N/A | AO32: N/A | AP32: N/A | AQ32: N/A | AR32: N/A | AS32: N/A
B33: =HLOOKUP(SUBSTITUTE(SUBSTITUTE(SUBSTITUTE(SUBSTITUTE(SUBSTITUTE(VCBW,"AMR_",""),"EVS_",""),"SO3_",""),"SO68_",""),"SO73_",""),$M$3:$O$75,ROW(B33)-ROW($M$3)+1,FALSE)&IF(ISBLANK(HLOOKUP(SUBSTITUTE(SUBSTITUTE(SUBSTITUTE(SUBSTITUTE(SUBSTITUTE(VCBW,"AMR_",""),"EVS_",""),"SO3_",""),"SO68_",""),"SO73_",""),$P$3:$R$75,ROW(B33)-ROW($P$3)+1,FALSE)), ""," / "&HLOOKUP(SUBSTITUTE(SUBSTITUTE(SUBSTITUTE(SUBSTITUTE(SUBSTITUTE(VCBW,"AMR_",""),"EVS_",""),"SO3_",""),"SO68_",""),"SO73_",""),$P$3:$R$75,ROW(B33)-ROW($P$3)+1,FALSE)) -> 5.7.4 / 7.7.3 | D33: min vol. | E33: =HLOOKUP(IF(OR("GSM"=Network,"WCDMA"=Network),"UMTS",IF(OR("VoLTE"=Network,"VoNR"=Network,"VoWiFi"=Network),"VoIMS",Network))&" "&VCBW,$T$3:$AF$75,ROW(E33)-ROW($T$3)+1,FALSE) -> 46 | F33: =HLOOKUP(IF(OR("GSM"=Network,"WCDMA"=Network),"UMTS",IF(OR("VoLTE"=Network,"VoNR"=Network,"VoWiFi"=Network),"VoIMS",Network))&" "&VCBW,$AG$3:$AS$75,ROW(E33)-ROW($AG$3)+1,FALSE) -> N/A | G33: dB | H33: 1 | M33: 5.7.4 | N33: 6.7.4 | O33: 7.7.4 | P33: 7.7.3 | Q33: 8.7.3 | R33: 9.7.3 | T33: 46 | U33: 46 | V33: 46 | W33: 46 | X33: 46 | Y33: 46 | Z33: 46 | AA33: 46 | AB33: 46 | AC33: 46 | AD33: 46 | AE33: 46 | AF33: 46 | AG33: N/A | AH33: N/A | AI33: N/A | AJ33: N/A | AK33: N/A | AL33: N/A | AM33: N/A | AN33: N/A | AO33: N/A | AP33: N/A | AQ33: N/A | AR33: N/A | AS33: N/A
A34: Distortion | B34: =HLOOKUP(SUBSTITUTE(SUBSTITUTE(SUBSTITUTE(SUBSTITUTE(SUBSTITUTE(VCBW,"AMR_",""),"EVS_",""),"SO3_",""),"SO68_",""),"SO73_",""),$M$3:$O$75,ROW(B34)-ROW($M$3)+1,FALSE)&IF(ISBLANK(HLOOKUP(SUBSTITUTE(SUBSTITUTE(SUBSTITUTE(SUBSTITUTE(SUBSTITUTE(VCBW,"AMR_",""),"EVS_",""),"SO3_",""),"SO68_",""),"SO73_",""),$P$3:$R$75,ROW(B34)-ROW($P$3)+1,FALSE)), ""," / "&HLOOKUP(SUBSTITUTE(SUBSTITUTE(SUBSTITUTE(SUBSTITUTE(SUBSTITUTE(VCBW,"AMR_",""),"EVS_",""),"SO3_",""),"SO68_",""),"SO73_",""),$P$3:$R$75,ROW(B34)-ROW($P$3)+1,FALSE)) -> 5.8.1 / 7.8.1 | C34: SND 1020Hz | E34: =HLOOKUP(IF(OR("GSM"=Network,"WCDMA"=Network),"UMTS",IF(OR("VoLTE"=Network,"VoNR"=Network,"VoWiFi"=Network),"VoIMS",Network))&" "&VCBW,$T$3:$AF$75,ROW(E34)-ROW($T$3)+1,FALSE) -> mask | F34: =HLOOKUP(IF(OR("GSM"=Network,"WCDMA"=Network),"UMTS",IF(OR("VoLTE"=Network,"VoNR"=Network,"VoWiFi"=Network),"VoIMS",Network))&" "&VCBW,$AG$3:$AS$75,ROW(E34)-ROW($AG$3)+1,FALSE) -> N/A | G34: N/A | H34: 1 | M34: 5.8.1 | N34: 6.8.1 | O34: 7.8.1 | P34: 7.8.1 | Q34: 8.8.1 | R34: 9.8.1 | T34: mask | U34: mask | V34: mask | W34: mask | X34: mask | Y34: mask | Z34: mask | AA34: mask | AB34: mask | AC34: mask | AD34: mask | AE34: mask | AF34: mask | AG34: N/A | AH34: N/A | AI34: N/A | AJ34: N/A | AK34: N/A | AL34: N/A | AM34: N/A | AN34: N/A | AO34: N/A | AP34: N/A | AQ34: N/A | AR34: N/A | AS34: N/A
B35: =HLOOKUP(SUBSTITUTE(SUBSTITUTE(SUBSTITUTE(SUBSTITUTE(SUBSTITUTE(VCBW,"AMR_",""),"EVS_",""),"SO3_",""),"SO68_",""),"SO73_",""),$M$3:$O$75,ROW(B35)-ROW($M$3)+1,FALSE)&IF(ISBLANK(HLOOKUP(SUBSTITUTE(SUBSTITUTE(SUBSTITUTE(SUBSTITUTE(SUBSTITUTE(VCBW,"AMR_",""),"EVS_",""),"SO3_",""),"SO68_",""),"SO73_",""),$P$3:$R$75,ROW(B35)-ROW($P$3)+1,FALSE)), ""," / "&HLOOKUP(SUBSTITUTE(SUBSTITUTE(SUBSTITUTE(SUBSTITUTE(SUBSTITUTE(VCBW,"AMR_",""),"EVS_",""),"SO3_",""),"SO68_",""),"SO73_",""),$P$3:$R$75,ROW(B35)-ROW($P$3)+1,FALSE)) -> × / 7.8.1 | C35: SND -4.7dBPa | E35: =HLOOKUP(IF(OR("GSM"=Network,"WCDMA"=Network),"UMTS",IF(OR("VoLTE"=Network,"VoNR"=Network,"VoWiFi"=Network),"VoIMS",Network))&" "&VCBW,$T$3:$AF$75,ROW(E35)-ROW($T$3)+1,FALSE) -> mask | F35: =HLOOKUP(IF(OR("GSM"=Network,"WCDMA"=Network),"UMTS",IF(OR("VoLTE"=Network,"VoNR"=Network,"VoWiFi"=Network),"VoIMS",Network))&" "&VCBW,$AG$3:$AS$75,ROW(E35)-ROW($AG$3)+1,FALSE) -> N/A | G35: N/A | H35: 1 | M35: × | N35: 6.8.1 | O35: 7.8.1 | P35: 7.8.1 | Q35: 8.8.1 | R35: 9.8.1 | T35: mask | U35: mask | V35: mask | W35: mask | X35: mask | Y35: mask | Z35: mask | AA35: mask | AB35: mask | AC35: mask | AD35: mask | AE35: mask | AF35: mask | AG35: N/A | AH35: N/A | AI35: N/A | AJ35: N/A | AK35: N/A | AL35: N/A | AM35: N/A | AN35: N/A | AO35: N/A | AP35: N/A | AQ35: N/A | AR35: N/A | AS35: N/A
B36: =HLOOKUP(SUBSTITUTE(SUBSTITUTE(SUBSTITUTE(SUBSTITUTE(SUBSTITUTE(VCBW,"AMR_",""),"EVS_",""),"SO3_",""),"SO68_",""),"SO73_",""),$M$3:$O$75,ROW(B36)-ROW($M$3)+1,FALSE)&IF(ISBLANK(HLOOKUP(SUBSTITUTE(SUBSTITUTE(SUBSTITUTE(SUBSTITUTE(SUBSTITUTE(VCBW,"AMR_",""),"EVS_",""),"SO3_",""),"SO68_",""),"SO73_",""),$P$3:$R$75,ROW(B36)-ROW($P$3)+1,FALSE)), ""," / "&HLOOKUP(SUBSTITUTE(SUBSTITUTE(SUBSTITUTE(SUBSTITUTE(SUBSTITUTE(VCBW,"AMR_",""),"EVS_",""),"SO3_",""),"SO68_",""),"SO73_",""),$P$3:$R$75,ROW(B36)-ROW($P$3)+1,FALSE)) -> 5.8.2 / 7.8.2 | C36: RCV 1020Hz | D36: man. vol. | E36: =HLOOKUP(IF(OR("GSM"=Network,"WCDMA"=Network),"UMTS",IF(OR("VoLTE"=Network,"VoNR"=Network,"VoWiFi"=Network),"VoIMS",Network))&" "&VCBW,$T$3:$AF$75,ROW(E36)-ROW($T$3)+1,FALSE) -> mask | F36: =HLOOKUP(IF(OR("GSM"=Network,"WCDMA"=Network),"UMTS",IF(OR("VoLTE"=Network,"VoNR"=Network,"VoWiFi"=Network),"VoIMS",Network))&" "&VCBW,$AG$3:$AS$75,ROW(E36)-ROW($AG$3)+1,FALSE) -> N/A | G36: N/A | H36: 1 | M36: 5.8.2 | N36: 6.8.2 | O36: 7.8.2 | P36: 7.8.2 | Q36: 8.8.2 | R36: 9.8.2 | T36: mask | U36: mask | V36: mask | W36: mask | X36: mask | Y36: mask | Z36: mask | AA36: mask | AB36: mask | AC36: mask | AD36: mask | AE36: mask | AF36: mask | AG36: N/A | AH36: N/A | AI36: N/A | AJ36: N/A | AK36: N/A | AL36: N/A | AM36: N/A | AN36: N/A | AO36: N/A | AP36: N/A | AQ36: N/A | AR36: N/A | AS36: N/A
B37: =HLOOKUP(SUBSTITUTE(SUBSTITUTE(SUBSTITUTE(SUBSTITUTE(SUBSTITUTE(VCBW,"AMR_",""),"EVS_",""),"SO3_",""),"SO68_",""),"SO73_",""),$M$3:$O$75,ROW(B37)-ROW($M$3)+1,FALSE)&IF(ISBLANK(HLOOKUP(SUBSTITUTE(SUBSTITUTE(SUBSTITUTE(SUBSTITUTE(SUBSTITUTE(VCBW,"AMR_",""),"EVS_",""),"SO3_",""),"SO68_",""),"SO73_",""),$P$3:$R$75,ROW(B37)-ROW($P$3)+1,FALSE)), ""," / "&HLOOKUP(SUBSTITUTE(SUBSTITUTE(SUBSTITUTE(SUBSTITUTE(SUBSTITUTE(VCBW,"AMR_",""),"EVS_",""),"SO3_",""),"SO68_",""),"SO73_",""),$P$3:$R$75,ROW(B37)-ROW($P$3)+1,FALSE)) -> 5.8.2 / 7.8.2 | D37: nom vol. | E37: =HLOOKUP(IF(OR("GSM"=Network,"WCDMA"=Network),"UMTS",IF(OR("VoLTE"=Network,"VoNR"=Network,"VoWiFi"=Network),"VoIMS",Network))&" "&VCBW,$T$3:$AF$75,ROW(E37)-ROW($T$3)+1,FALSE) -> mask | F37: =HLOOKUP(IF(OR("GSM"=Network,"WCDMA"=Network),"UMTS",IF(OR("VoLTE"=Network,"VoNR"=Network,"VoWiFi"=Network),"VoIMS",Network))&" "&VCBW,$AG$3:$AS$75,ROW(E37)-ROW($AG$3)+1,FALSE) -> N/A | G37: N/A | H37: 1 | M37: 5.8.2 | N37: 6.8.2 | O37: 7.8.2 | P37: 7.8.2 | Q37: 8.8.2 | R37: 9.8.2 | T37: mask | U37: mask | V37: mask | W37: mask | X37: mask | Y37: mask | Z37: mask | AA37: mask | AB37: mask | AC37: mask | AD37: mask | AE37: mask | AF37: mask | AG37: N/A | AH37: N/A | AI37: N/A | AJ37: N/A | AK37: N/A | AL37: N/A | AM37: N/A | AN37: N/A | AO37: N/A | AP37: N/A | AQ37: N/A | AR37: N/A | AS37: N/A
B38: =HLOOKUP(SUBSTITUTE(SUBSTITUTE(SUBSTITUTE(SUBSTITUTE(SUBSTITUTE(VCBW,"AMR_",""),"EVS_",""),"SO3_",""),"SO68_",""),"SO73_",""),$M$3:$O$75,ROW(B38)-ROW($M$3)+1,FALSE)&IF(ISBLANK(HLOOKUP(SUBSTITUTE(SUBSTITUTE(SUBSTITUTE(SUBSTITUTE(SUBSTITUTE(VCBW,"AMR_",""),"EVS_",""),"SO3_",""),"SO68_",""),"SO73_",""),$P$3:$R$75,ROW(B38)-ROW($P$3)+1,FALSE)), ""," / "&HLOOKUP(SUBSTITUTE(SUBSTITUTE(SUBSTITUTE(SUBSTITUTE(SUBSTITUTE(VCBW,"AMR_",""),"EVS_",""),"SO3_",""),"SO68_",""),"SO73_",""),$P$3:$R$75,ROW(B38)-ROW($P$3)+1,FALSE)) -> 5.8.2 / 7.8.2 | C38: RCV -16dBm0 | D38: max vol. | E38: =HLOOKUP(IF(OR("GSM"=Network,"WCDMA"=Network),"UMTS",IF(OR("VoLTE"=Network,"VoNR"=Network,"VoWiFi"=Network),"VoIMS",Network))&" "&VCBW,$T$3:$AF$75,ROW(E38)-ROW($T$3)+1,FALSE) -> mask | F38: =HLOOKUP(IF(OR("GSM"=Network,"WCDMA"=Network),"UMTS",IF(OR("VoLTE"=Network,"VoNR"=Network,"VoWiFi"=Network),"VoIMS",Network))&" "&VCBW,$AG$3:$AS$75,ROW(E38)-ROW($AG$3)+1,FALSE) -> N/A | G38: N/A | H38: 1 | M38: 5.8.2 | N38: 6.8.2 | O38: 7.8.2 | P38: 7.8.2 | Q38: 8.8.2 | R38: 9.8.2 | T38: mask | U38: mask | V38: mask | W38: mask | X38: mask | Y38: mask | Z38: mask | AA38: mask | AB38: mask | AC38: mask | AD38: mask | AE38: mask | AF38: mask | AG38: N/A | AH38: N/A | AI38: N/A | AJ38: N/A | AK38: N/A | AL38: N/A | AM38: N/A | AN38: N/A | AO38: N/A | AP38: N/A | AQ38: N/A | AR38: N/A | AS38: N/A
B39: =HLOOKUP(SUBSTITUTE(SUBSTITUTE(SUBSTITUTE(SUBSTITUTE(SUBSTITUTE(VCBW,"AMR_",""),"EVS_",""),"SO3_",""),"SO68_",""),"SO73_",""),$M$3:$O$75,ROW(B39)-ROW($M$3)+1,FALSE)&IF(ISBLANK(HLOOKUP(SUBSTITUTE(SUBSTITUTE(SUBSTITUTE(SUBSTITUTE(SUBSTITUTE(VCBW,"AMR_",""),"EVS_",""),"SO3_",""),"SO68_",""),"SO73_",""),$P$3:$R$75,ROW(B39)-ROW($P$3)+1,FALSE)), ""," / "&HLOOKUP(SUBSTITUTE(SUBSTITUTE(SUBSTITUTE(SUBSTITUTE(SUBSTITUTE(VCBW,"AMR_",""),"EVS_",""),"SO3_",""),"SO68_",""),"SO73_",""),$P$3:$R$75,ROW(B39)-ROW($P$3)+1,FALSE)) -> 5.8.2 / 7.8.2 | D39: nom vol. | E39: =HLOOKUP(IF(OR("GSM"=Network,"WCDMA"=Network),"UMTS",IF(OR("VoLTE"=Network,"VoNR"=Network,"VoWiFi"=Network),"VoIMS",Network))&" "&VCBW,$T$3:$AF$75,ROW(E39)-ROW($T$3)+1,FALSE) -> mask | F39: =HLOOKUP(IF(OR("GSM"=Network,"WCDMA"=Network),"UMTS",IF(OR("VoLTE"=Network,"VoNR"=Network,"VoWiFi"=Network),"VoIMS",Network))&" "&VCBW,$AG$3:$AS$75,ROW(E39)-ROW($AG$3)+1,FALSE) -> N/A | G39: N/A | H39: 1 | M39: 5.8.2 | N39: 6.8.2 | O39: 7.8.2 | P39: 7.8.2 | Q39: 8.8.2 | R39: 9.8.2 | T39: mask | U39: mask | V39: mask | W39: mask | X39: mask | Y39: mask | Z39: mask | AA39: mask | AB39: mask | AC39: mask | AD39: mask | AE39: mask | AF39: mask | AG39: N/A | AH39: N/A | AI39: N/A | AJ39: N/A | AK39: N/A | AL39: N/A | AM39: N/A | AN39: N/A | AO39: N/A | AP39: N/A | AQ39: N/A | AR39: N/A | AS39: N/A
A40: Delay | B40: =HLOOKUP(SUBSTITUTE(SUBSTITUTE(SUBSTITUTE(SUBSTITUTE(SUBSTITUTE(VCBW,"AMR_",""),"EVS_",""),"SO3_",""),"SO68_",""),"SO73_",""),$M$3:$O$75,ROW(B40)-ROW($M$3)+1,FALSE)&IF(ISBLANK(HLOOKUP(SUBSTITUTE(SUBSTITUTE(SUBSTITUTE(SUBSTITUTE(SUBSTITUTE(VCBW,"AMR_",""),"EVS_",""),"SO3_",""),"SO68_",""),"SO73_",""),$P$3:$R$75,ROW(B40)-ROW($P$3)+1,FALSE)), ""," / "&HLOOKUP(SUBSTITUTE(SUBSTITUTE(SUBSTITUTE(SUBSTITUTE(SUBSTITUTE(VCBW,"AMR_",""),"EVS_",""),"SO3_",""),"SO68_",""),"SO73_",""),$P$3:$R$75,ROW(B40)-ROW($P$3)+1,FALSE)) -> 5.12.1 / 7.10 | C40: Round-trip | D40: TS+TR | E40: =HLOOKUP(IF(OR("GSM"=Network,"WCDMA"=Network),"UMTS",IF(OR("VoLTE"=Network,"VoNR"=Network,"VoWiFi"=Network),"VoIMS",Network))&" "&VCBW,$T$3:$AF$75,ROW(E40)-ROW($T$3)+1,FALSE) -> 0 | F40: =HLOOKUP(IF(OR("GSM"=Network,"WCDMA"=Network),"UMTS",IF(OR("VoLTE"=Network,"VoNR"=Network,"VoWiFi"=Network),"VoIMS",Network))&" "&VCBW,$AG$3:$AS$75,ROW(E40)-ROW($AG$3)+1,FALSE) -> 190 | G40: ms | H40: 1 | M40: 5.12.1 | N40: 6.11.1 | O40: 7.11.1 | P40: 7.10 | Q40: 8.10 | R40: 9.10 | T40: 0 | U40: 0 | V40: 0 | W40: 0 | X40: 0 | Y40: 0 | Z40: 0 | AA40: 0 | AB40: 0 | AC40: 0 | AD40: 0 | AE40: 0 | AF40: 0 | AG40: 220 | AH40: 220 | AI40: 190 | AJ40: 190 | AK40: 190 | AL40: 190 | AM40: 190 | AN40: 220 | AO40: 220 | AP40: 220 | AQ40: 220 | AR40: N/A | AS40: N/A
A41: Echo control characteristics | B41: =HLOOKUP(SUBSTITUTE(SUBSTITUTE(SUBSTITUTE(SUBSTITUTE(SUBSTITUTE(VCBW,"AMR_",""),"EVS_",""),"SO3_",""),"SO68_",""),"SO73_",""),$M$3:$O$75,ROW(B41)-ROW($M$3)+1,FALSE)&IF(ISBLANK(HLOOKUP(SUBSTITUTE(SUBSTITUTE(SUBSTITUTE(SUBSTITUTE(SUBSTITUTE(VCBW,"AMR_",""),"EVS_",""),"SO3_",""),"SO68_",""),"SO73_",""),$P$3:$R$75,ROW(B41)-ROW($P$3)+1,FALSE)), ""," / "&HLOOKUP(SUBSTITUTE(SUBSTITUTE(SUBSTITUTE(SUBSTITUTE(SUBSTITUTE(VCBW,"AMR_",""),"EVS_",""),"SO3_",""),"SO68_",""),"SO73_",""),$P$3:$R$75,ROW(B41)-ROW($P$3)+1,FALSE)) -> 5.13.1 / 7.11 | C41: Short DT Class | D41: A1 | E41: =HLOOKUP(IF(OR("GSM"=Network,"WCDMA"=Network),"UMTS",IF(OR("VoLTE"=Network,"VoNR"=Network,"VoWiFi"=Network),"VoIMS",Network))&" "&VCBW,$T$3:$AF$75,ROW(E41)-ROW($T$3)+1,FALSE) -> 0.9 | F41: =HLOOKUP(IF(OR("GSM"=Network,"WCDMA"=Network),"UMTS",IF(OR("VoLTE"=Network,"VoNR"=Network,"VoWiFi"=Network),"VoIMS",Network))&" "&VCBW,$AG$3:$AS$75,ROW(E41)-ROW($AG$3)+1,FALSE) -> 1 | G41: % | H41: 2 | M41: 5.13.1 | N41: 6.12.1 | O41: 7.12.1 | P41: 7.11 | Q41: 8.11 | R41: 9.11 | T41: 0.9 | U41: 0.9 | V41: 0.9 | W41: 0.9 | X41: 0.9 | Y41: 0.9 | Z41: 0.9 | AA41: 0.9 | AB41: 0.9 | AC41: 0.9 | AD41: 0.9 | AE41: 0.9 | AF41: 0.9 | AG41: 1 | AH41: 1 | AI41: 1 | AJ41: 1 | AK41: 1 | AL41: 1 | AM41: 1 | AN41: 1 | AO41: 1 | AP41: 1 | AQ41: 1 | AR41: 1 | AS41: 1
...

Sheet Handsfree
A1: Voice Tuning Checklist - Handsfree
A3: Test Condition | E3: Criteria | I3: =Report!B15 -> VoLTE | J3: =Report!C15 -> AMR_NB | K3: =Report!D15 -> 12.2kbit/s | M3: NB | N3: WB | O3: SWB | P3: NB | Q3: WB | R3: SWB | T3: UMTS AMR_NB | U3: UMTS AMR_WB | V3: VoIMS AMR_NB | W3: VoIMS AMR_WB | X3: VoIMS EVS_NB | Y3: VoIMS EVS_WB | Z3: VoIMS EVS_SWB | AA3: CDMA SO3_NB | AB3: CDMA SO68_NB | AC3: CDMA SO73_NB | AD3: CDMA SO73_WB | AE3: VoIP WB | AF3: VoIP SWB | AG3: UMTS AMR_NB | AH3: UMTS AMR_WB | AI3: VoIMS AMR_NB | AJ3: VoIMS AMR_WB | AK3: VoIMS EVS_NB | AL3: VoIMS EVS_WB | AM3: VoIMS EVS_SWB | AN3: CDMA SO3_NB | AO3: CDMA SO68_NB | AP3: CDMA SO73_NB | AQ3: CDMA SO73_WB | AR3: VoIP WB | AS3: VoIP SWB
A4: Item | B4: Standard | C4: Subitem | D4: Settings | E4: lower | F4: upper | G4: unit | H4: type | I4: =IF(ISBLANK(Report!B8),"",ISBLANK(Report!B8)) | J4: =IF(ISBLANK(Report!C8),"",ISBLANK(Report!C8)) | K4: =IF(ISBLANK(Report!D8),"",ISBLANK(Report!D8))
A5: 3GPP TS126.132 | M5: NB | N5: WB | O5: SWB | P5: NB | Q5: WB | R5: SWB | T5: AMR_NB | U5: AMR_WB | V5: AMR_NB | W5: AMR_WB | X5: EVS_NB | Y5: EVS_WB | Z5: EVS_SWB | AA5: SO3_NB | AB5: SO68_NB | AC5: SO73_NB | AD5: SO73_WB | AE5: WB | AF5: SWB | AG5: AMR_NB | AH5: AMR_WB | AI5: AMR_NB | AJ5: AMR_WB | AK5: EVS_NB | AL5: EVS_WB | AM5: EVS_SWB | AN5: SO3_NB | AO5: SO68_NB | AP5: SO73_NB | AQ5: SO73_WB | AR5: WB | AS5: SWB
A6: Overall loss/loudness ratings | B6: =HLOOKUP(SUBSTITUTE(SUBSTITUTE(SUBSTITUTE(SUBSTITUTE(SUBSTITUTE(VCBW,"AMR_",""),"EVS_",""),"SO3_",""),"SO68_",""),"SO73_",""),$M$3:$O$57,ROW(B6)-ROW($M$3)+1,FALSE)&IF(ISBLANK(HLOOKUP(SUBSTITUTE(SUBSTITUTE(SUBSTITUTE(SUBSTITUTE(SUBSTITUTE(VCBW,"AMR_",""),"EVS_",""),"SO3_",""),"SO68_",""),"SO73_",""),$P$3:$R$57,ROW(B6)-ROW($P$3)+1,FALSE)), ""," / "&HLOOKUP(SUBSTITUTE(SUBSTITUTE(SUBSTITUTE(SUBSTITUTE(SUBSTITUTE(VCBW,"AMR_",""),"EVS_",""),"SO3_",""),"SO68_",""),"SO73_",""),$P$3:$R$57,ROW(B6)-ROW($P$3)+1,FALSE)) -> 5.2.4 / 7.2.4.1 | C6: Sending (SLR) | E6: =HLOOKUP(IF(OR("GSM"=Network,"WCDMA"=Network),"UMTS",IF(OR("VoLTE"=Network,"VoNR"=Network,"VoWiFi"=Network),"VoIMS",Network))&" "&VCBW,$T$3:$AF$57,ROW(E6)-ROW($T$3)+1,FALSE) -> 9 | F6: =HLOOKUP(IF(OR("GSM"=Network,"WCDMA"=Network),"UMTS",IF(OR("VoLTE"=Network,"VoNR"=Network,"VoWiFi"=Network),"VoIMS",Network))&" "&VCBW,$AG$3:$AS$57,ROW(E6)-ROW($AG$3)+1,FALSE) -> 17 | G6: dB | H6: 1 | M6: 5.2.4 | N6: 6.2.4 | O6: 7.2.4 | P6: 7.2.4.1 | Q6: 8.2.4.1 | R6: 9.2.4.1 | T6: 9 | U6: 9 | V6: 9 | W6: 9 | X6: 9 | Y6: 9 | Z6: 9 | AA6: 9 | AB6: 9 | AC6: 9 | AD6: 9 | AE6: 9 | AF6: 9 | AG6: 17 | AH6: 17 | AI6: 17 | AJ6: 17 | AK6: 17 | AL6: 17 | AM6: 17 | AN6: 17 | AO6: 17 | AP6: 17 | AQ6: 17 | AR6: 17 | AS6: 17
B7: =HLOOKUP(SUBSTITUTE(SUBSTITUTE(SUBSTITUTE(SUBSTITUTE(SUBSTITUTE(VCBW,"AMR_",""),"EVS_",""),"SO3_",""),"SO68_",""),"SO73_",""),$M$3:$O$57,ROW(B7)-ROW($M$3)+1,FALSE)&IF(ISBLANK(HLOOKUP(SUBSTITUTE(SUBSTITUTE(SUBSTITUTE(SUBSTITUTE(SUBSTITUTE(VCBW,"AMR_",""),"EVS_",""),"SO3_",""),"SO68_",""),"SO73_",""),$P$3:$R$57,ROW(B7)-ROW($P$3)+1,FALSE)), ""," / "&HLOOKUP(SUBSTITUTE(SUBSTITUTE(SUBSTITUTE(SUBSTITUTE(SUBSTITUTE(VCBW,"AMR_",""),"EVS_",""),"SO3_",""),"SO68_",""),"SO73_",""),$P$3:$R$57,ROW(B7)-ROW($P$3)+1,FALSE)) -> 5.2.4 / 7.2.4.2 | C7: Receiving (RLR) | D7: max vol. | E7: =HLOOKUP(IF(OR("GSM"=Network,"WCDMA"=Network),"UMTS",IF(OR("VoLTE"=Network,"VoNR"=Network,"VoWiFi"=Network),"VoIMS",Network))&" "&VCBW,$T$3:$AF$57,ROW(E7)-ROW($T$3)+1,FALSE) -> N/A | F7: =HLOOKUP(IF(OR("GSM"=Network,"WCDMA"=Network),"UMTS",IF(OR("VoLTE"=Network,"VoNR"=Network,"VoWiFi"=Network),"VoIMS",Network))&" "&VCBW,$AG$3:$AS$57,ROW(E7)-ROW($AG$3)+1,FALSE) -> 9 | G7: dB | H7: 1 | M7: 5.2.4 | N7: 6.2.4 | O7: 7.2.4 | P7: 7.2.4.2 | Q7: 8.2.4.2 | R7: 9.2.4.2 | T7: N/A | U7: N/A | V7: N/A | W7: N/A | X7: N/A | Y7: N/A | Z7: N/A | AA7: N/A | AB7: N/A | AC7: N/A | AD7: N/A | AE7: N/A | AF7: N/A | AG7: 9 | AH7: 9 | AI7: 9 | AJ7: 9 | AK7: 9 | AL7: 9 | AM7: 9 | AN7: 9 | AO7: 9 | AP7: 9 | AQ7: 9 | AR7: 9 | AS7: 9
B8: =HLOOKUP(SUBSTITUTE(SUBSTITUTE(SUBSTITUTE(SUBSTITUTE(SUBSTITUTE(VCBW,"AMR_",""),"EVS_",""),"SO3_",""),"SO68_",""),"SO73_",""),$M$3:$O$57,ROW(B8)-ROW($M$3)+1,FALSE)&IF(ISBLANK(HLOOKUP(SUBSTITUTE(SUBSTITUTE(SUBSTITUTE(SUBSTITUTE(SUBSTITUTE(VCBW,"AMR_",""),"EVS_",""),"SO3_",""),"SO68_",""),"SO73_",""),$P$3:$R$57,ROW(B8)-ROW($P$3)+1,FALSE)), ""," / "&HLOOKUP(SUBSTITUTE(SUBSTITUTE(SUBSTITUTE(SUBSTITUTE(SUBSTITUTE(VCBW,"AMR_",""),"EVS_",""),"SO3_",""),"SO68_",""),"SO73_",""),$P$3:$R$57,ROW(B8)-ROW($P$3)+1,FALSE)) -> 5.2.4 / 7.2.4.2 | D8: max-1 vol. | E8: =HLOOKUP(IF(OR("GSM"=Network,"WCDMA"=Network),"UMTS",IF(OR("VoLTE"=Network,"VoNR"=Network,"VoWiFi"=Network),"VoIMS",Network))&" "&VCBW,$T$3:$AF$57,ROW(E8)-ROW($T$3)+1,FALSE) -> N/A | F8: =HLOOKUP(IF(OR("GSM"=Network,"WCDMA"=Network),"UMTS",IF(OR("VoLTE"=Network,"VoNR"=Network,"VoWiFi"=Network),"VoIMS",Network))&" "&VCBW,$AG$3:$AS$57,ROW(E8)-ROW($AG$3)+1,FALSE) -> 12 | G8: dB | H8: 4 | J8: × | K8: × | M8: 5.2.4 | N8: 6.2.4 | O8: 7.2.4 | P8: 7.2.4.2 | Q8: 8.2.4.2 | R8: 9.2.4.2 | T8: N/A | U8: N/A | V8: N/A | W8: N/A | X8: N/A | Y8: N/A | Z8: N/A | AA8: N/A | AB8: N/A | AC8: N/A | AD8: N/A | AE8: N/A | AF8: N/A | AG8: 12 | AH8: 12 | AI8: 12 | AJ8: 12 | AK8: 12 | AL8: 12 | AM8: 12 | AN8: 12 | AO8: 12 | AP8: 12 | AQ8: 12 | AR8: 12 | AS8: 12
B9: =HLOOKUP(SUBSTITUTE(SUBSTITUTE(SUBSTITUTE(SUBSTITUTE(SUBSTITUTE(VCBW,"AMR_",""),"EVS_",""),"SO3_",""),"SO68_",""),"SO73_",""),$M$3:$O$57,ROW(B9)-ROW($M$3)+1,FALSE)&IF(ISBLANK(HLOOKUP(SUBSTITUTE(SUBSTITUTE(SUBSTITUTE(SUBSTITUTE(SUBSTITUTE(VCBW,"AMR_",""),"EVS_",""),"SO3_",""),"SO68_",""),"SO73_",""),$P$3:$R$57,ROW(B9)-ROW($P$3)+1,FALSE)), ""," / "&HLOOKUP(SUBSTITUTE(SUBSTITUTE(SUBSTITUTE(SUBSTITUTE(SUBSTITUTE(VCBW,"AMR_",""),"EVS_",""),"SO3_",""),"SO68_",""),"SO73_",""),$P$3:$R$57,ROW(B9)-ROW($P$3)+1,FALSE)) -> 5.2.4 / 7.2.4.2 | D9: max-2 vol. | E9: =HLOOKUP(IF(OR("GSM"=Network,"WCDMA"=Network),"UMTS",IF(OR("VoLTE"=Network,"VoNR"=Network,"VoWiFi"=Network),"VoIMS",Network))&" "&VCBW,$T$3:$AF$57,ROW(E9)-ROW($T$3)+1,FALSE) -> N/A | F9: =HLOOKUP(IF(OR("GSM"=Network,"WCDMA"=Network),"UMTS",IF(OR("VoLTE"=Network,"VoNR"=Network,"VoWiFi"=Network),"VoIMS",Network))&" "&VCBW,$AG$3:$AS$57,ROW(E9)-ROW($AG$3)+1,FALSE) -> 15 | G9: dB | H9: 4 | J9: × | K9: × | M9: 5.2.4 | N9: 6.2.4 | O9: 7.2.4 | P9: 7.2.4.2 | Q9: 8.2.4.2 | R9: 9.2.4.2 | T9: N/A | U9: N/A | V9: N/A | W9: N/A | X9: N/A | Y9: N/A | Z9: N/A | AA9: N/A | AB9: N/A | AC9: N/A | AD9: N/A | AE9: N/A | AF9: N/A | AG9: 15 | AH9: 15 | AI9: 15 | AJ9: 15 | AK9: 15 | AL9: 15 | AM9: 15 | AN9: 15 | AO9: 15 | AP9: 15 | AQ9: 15 | AR9: 15 | AS9: 15
